Workbook
Name __MXH08: #REF!
Name _006: #REF!
Name _1: [1]原材料!$A$1:$R$945
Name _1_1223: #REF!
Name _1223: #REF!
Name _123: #REF!
Name _12456: #REF!
Name _2_1223: #REF!
Name _2_123: #REF!
Name _2成本: #REF!
Name _2电力收入: #REF!
Name _2年成本: #REF!
Name _2年收入: #REF!
Name _3.1: #N/A
Name _3.2: #N/A
Name _3.U: #N/A
Name _3_12456: #REF!
Name _3年成本: #REF!
Name _3年收入: #REF!
Name _4_123: #REF!
Name _4_898: #REF!
Name _4年成本: #REF!
Name _4年收入: #REF!
Name _5年成本: #REF!
Name _5年收入: #REF!
Name _6_12456: #REF!
Name _8_898: #REF!
Name _898: #REF!
Name _A91: #REF!
Name _A99: #REF!
Name _MXH08: #REF!
Name Apr: #REF!="04月"
Name ASFJDFLDFSLALFA: #REF!
Name Aug: #REF!="08月"
Name b: #REF!
Name bianzhi: #REF!
Name bianzhiriqi: #REF!
Name butie: #REF!
Name CanSave: FALSE
Name COL_NUM: [2]细节测试审计抽样!$U$76
Name Confidence_Factor: [2]细节测试审计抽样!$W$73:$Z$76
Name daqu: #REF!
Name DATA: OFFSET([3]汇总明细!$A$1,,,COUNTA([3]汇总明细!$A$1:$A$65536),COUNTA([3]汇总明细!$A$1:$IV$1))
Name DATA1: OFFSET([3]进销存模板!$A$1,,,COUNTA([3]进销存模板!$A$1:$A$65536),COUNTA([3]进销存模板!$A$1:$IV$1))
Name data2: [4]销售分公司!$H$5:$H$7,[4]销售分公司!$H$9:$H$11,[4]销售分公司!$H$13:$H$14,[4]销售分公司!$H$16
Name data3: [4]销售分公司!$F$22:$F$26,[4]销售分公司!$F$28:$F$30,[4]销售分公司!$F$32:$F$33,[4]销售分公司!$F$35
Name data4: [4]销售分公司!$H$24:$H$26,[4]销售分公司!$H$28:$H$30,[4]销售分公司!$H$32:$H$33,[4]销售分公司!$H$35
Name Database: #REF!
Name DBPATH: "湖北杰之行股份2015_数据.cxt"
Name Dec: #REF!="12月"
Name diaop: '[5]数据库(万元)'!$L$2:$L$24990
Name dpe: #REF!
Name dpjb: #REF!
Name dpname: OFFSET(#REF!,ROW()-11,MATCH(#REF!,#REF!,)-1)
Name dpyt: #REF!
Name dq: #REF!
Name dxn: [6]dxnsjtempsheet!$A$1:$G$65536
Name E: [7]Sheet1!$A$9
Name Feb: #REF!="02月"
Name FeiY: #REF!

Sheet 封面
A1: 收益法评估明细表
A2: 1 | B2: 被评估单位：福建卫东新能源股份有限公司
A3: 2 | B3: 评估基准日： | C3: 2017年12月31日
A4: 3 | B4: 企业负责人： | C4: 李恒
A5: 4 | B5: 财务负责人： | C5: 林岗
A6: 5 | B6: 填表人： | C6: 林岗
A7: 6 | B7: 填表日期： | C7: 43179
A9: 7 | B9: 评估机构： | C9: 万隆（上海）资产评估有限公司
A10: 8 | B10: 法人代表人： | C10: 刘宏
A11: 9 | B11: 项目负责人：
A12: 10 | B12: 签字评估师：
B15: 基本要求
A16: 1 | B16: 申报表由企业根据实际情况填写，相关数据应该与审计报告/会计报表一致。
A17: 2 | B17: （1）绿色应由企业填报。（2）黄色表格可根据实际情况选择是否填列。（3）红色表格由评估人员评估计算使用。
A18: 3 | B18: 预测总要求 | C18: 数据和财务指标应与历史情况衔接，如果出现超常规变化（这也是审核的重点），应有充分的理由认为预测可实现。
B19: 主营收入预测要点 | C19: （1）市场需求容量；（2）企业产能；（3）企业前几年销量及市场占有率；（4）行业竞争企业在行业中的竞争能力（优劣势分析）；（5）行业龙头企业的销量情况；（6）企业在细分产品领域、营销和宣传方面的策略；（7）企业发展规划。（8）支出企业预期收益实现的各种资源是否有保障。
B20: 主营业务成本预测要点 | C20: 基本应与历史情况一致。
B21: 期间费用预测要点 | C21: 基本应与历史情况相当，但应考虑规模效益导致的变化。同时可参考行业企业的费率情况。
C22: 注意各科目中，是否存在溢余资产、非经营性资产和负债。

Sheet 资产负债分析调整表
D1: 资产负债分析调整表
A2: =封面!B2 -> 被评估单位：福建卫东新能源股份有限公司 | F2: 评估基准日： | G2: =封面!C3 -> 2017年12月31日
A4: 序号 | B4: 项目\年份 | C4: ='[34]表I-2调整后利润表'!B6&"年12月31日" -> 2015年12月31日 | D4: ='[34]表I-2调整后利润表'!C6&"年12月31日" -> 2016年12月31日 | E4: ='[34]表I-1近年利润表'!D6&"年12月31日" -> 2017年12月31日
C5: 账面值 | D5: 账面值 | E5: 账面值 | F5: 其中：非经营性资产 | G5: 经营性资产
A6: 1 | B6: 一、流动资产合计 | C6: =C7+C8+C9+C10+C11+C12+C14+C15+C13+C16+C17+C18+C19 -> 83116651 | D6: =D7+D8+D9+D10+D11+D12+D14+D15+D13+D16+D17+D18+D19 -> 76673213 | E6: =SUM(E7:E19) -> 70610292 | F6: =F7+F8+F9+F10+F11+F12+F13+F14+F15+F16+F17+F18+F19 -> 60511670 | G6: =E6-F6 -> 10098622
A7: 2 | B7: 货币资金 | C7: 6628414.3 | D7: 117476.61 | E7: 64080.64 | G7: =E7-F7 -> 64080.64
A8: 3 | B8: 交易性金融资产净额 | C8: 619575 | D8: 0 | E8: 0 | G8: =E8-F8 -> 0
A9: 4 | B9: 应收票据 | D9: 1900000 | E9: 0 | G9: =E9-F9 -> 0
A10: 5 | B10: 应收股利(应收利润) | D10: 0 | E10: 0 | G10: =E10-F10 -> 0
A11: 6 | B11: 应收利息 | D11: 0 | E11: 0 | G11: =E11-F11 -> 0
A12: 7 | B12: 应收账款净额 | C12: 3440854.1 | D12: 8809335.9 | E12: 3259831.8 | G12: =E12-F12 -> 3259831.8
A13: 8 | B13: 其他应收款净额 | C13: 64618993 | D13: 62267599 | E13: 59701035 | F13: 60511670 | G13: =E14-F13 -> -58230227
A14: 9 | B14: 预付帐款 | C14: 4346083.5 | D14: 896722.35 | E14: 2281443.4 | G14: =E14-F14 -> 2281443.4
A15: 10 | B15: 应收补贴款 | G15: =E13-F15 -> 59701035
A16: 11 | B16: 存货净额 | C16: 3462731.8 | D16: 2682078.7 | E16: 5303901.6 | G16: =E16-F16 -> 5303901.6
A17: 12 | B17: 待摊费用 | E17: 0 | G17: =E17-F17 -> 0
A18: 13 | B18: 一年内到期的非流动资产
A19: 14 | B19: 其他流动资产 | G19: =E19-F19 -> 0
A20: 15 | B20: 二、非流动资产合计 | C20: =C21+C22+C23+C24+C25+C26+C32+C33+C34+C35+C36+C37+C38+C39+C40+C41+C42 -> 19411960 | D20: =D21+D22+D23+D24+D25+D26+D32+D33+D34+D35+D36+D37+D38+D39+D40+D41+D42 -> 35364860 | E20: =E21+E22+E23+E24+E25+E26+E32+E33+E34+E35+E36+E37+E38+E39+E40+E41+E42 -> 34674500 | F20: =F21+F22+F23+F24+F25+F26+F32+F33+F34+F35+F36+F37+F38+F39+F40+F41+F42 -> 15000000 | G20: =E20-F20 -> 19674500
A21: 16 | B21: 可供出售金融资产净额 | C21: 0 | D21: 0 | E21: 0 | G21: =E21-F21 -> 0
A22: 17 | B22: 持有至到期投资净额 | C22: 0 | D22: 0 | E22: 0 | G22: =E22-F22 -> 0
A23: 18 | B23: 长期股权投资净额 | C23: 0 | D23: 15000000 | E23: 15000000 | F23: =E23 -> 15000000 | G23: =E23-F23 -> 0
A24: 19 | B24: 长期应收款 | C24: 0 | D24: 0 | E24: 0 | G24: =E24-F24 -> 0
A25: 20 | B25: 投资性房地产 | C25: 0 | G25: =E25-F25 -> 0
A26: 21 | B26: 固定资产 | C26: =C31 -> 11310294 | D26: =D31 -> 12444368 | E26: =E31 -> 11938056 | G26: =E26-F26 -> 11938056
A27: 22 | B27: 固定资产原价 | C27: 11942890 | D27: 14780443 | E27: 16120369 | G27: =E27-F27 -> 16120369
A28: 23 | B28: 减：累计折旧 | C28: 632596.26 | D28: 2336075.6 | E28: 4182313.5 | G28: =E28-F28 -> 4182313.5
A29: 24 | B29: 固定资产净值 | C29: =C27-C28 -> 11310294 | D29: =D27-D28 -> 12444368 | E29: =E27-E28 -> 11938056 | G29: =E29-F29 -> 11938056
A30: 25 | B30: 减：固定资产减值准备 | C30: 0 | D30: 0 | E30: 0 | G30: =E30-F30 -> 0
A31: 26 | B31: 固定资产净额 | C31: =C29-C30 -> 11310294 | D31: =D29-D30 -> 12444368 | E31: =E29-E30 -> 11938056 | F31: =F29-F30 -> 0 | G31: =E31-F31 -> 11938056
A32: 27 | B32: 工程物资 | C32: 0 | D32: 0 | E32: 0 | G32: =E32-F32 -> 0
A33: 28 | B33: 在建工程 | G33: =E33-F33 -> 0
A34: 29 | B34: 固定资产清理 | C34: 0 | D34: 0 | E34: 0 | G34: =E34-F34 -> 0
A35: 30 | B35: 生产性生物资产净额 | C35: 0 | D35: 0 | E35: 0 | G35: =E35-F35 -> 0
A36: 31 | B36: 油气资产净值 | C36: 0 | D36: 0 | E36: 0 | G36: =E36-F36 -> 0
A37: 32 | B37: 开发支出 | C37: 0 | D37: 0 | E37: 0 | G37: =E37-F37 -> 0
A38: 33 | B38: 商誉 | C38: 0 | D38: 0 | E38: 0 | G38: =E38-F38 -> 0
A39: 34 | B39: 无形资产净额 | C39: 4812245.4 | D39: 4496075.8 | E39: 4165377.7 | G39: =E39-F39 -> 4165377.7
A40: 35 | B40: 长期待摊费用 | G40: =E40-F40 -> 0
A41: 36 | B41: 其他非流动资产 | C41: 0 | D41: 0 | E41: 0 | G41: =E41-F41 -> 0
...

Sheet 利润分析调整表
C1: 利润表分析调整表
A3: =封面!B2 -> 被评估单位：福建卫东新能源股份有限公司 | D3: 评估基准日 | E3: =封面!C3 -> 2017年12月31日
E5: 单位：元
A6: 项目 \ 年份 | B6: ='[34]表I-1近年利润表'!B6 -> 2015 | C6: ='[34]表I-1近年利润表'!C6 -> 2016 | D6: ='[34]表I-1近年利润表'!D6 -> 2017 | E6: 调整分析说明
A7: ='[34]表I-1近年利润表'!A7 -> 一、营业总收入 | B7: =B8+B9 -> 2935047.1 | C7: =C8+C9 -> 10814268 | D7: =D8+D9 -> 3114175.7
A8: ='[34]表I-1近年利润表'!A8 -> 其中：主营业务收入 | B8: 2935047.1 | C8: 10473622 | D8: =2167194.48+946981.23 -> 3114175.7
A9: ='[34]表I-1近年利润表'!A9 -> 其他业务收入 | B9: 0 | C9: 340646.29
A10: ='[34]表I-1近年利润表'!A10 -> 二、营业总成本 | B10: =B11+B15+B16+B17+B18+B19 -> 11306485 | C10: =C11+C15+C16+C17+C18+C19 -> 15930623 | D10: =D11+D15+D16+D17+D18+D19 -> 10507876
A11: ='[34]表I-1近年利润表'!A11 -> 其中:营业成本 | B11: =B12+B14 -> 2114358.2 | C11: =C12+C14 -> 7060951.5 | D11: =D12+D14 -> 4577497.7
A12: ='[34]表I-1近年利润表'!A12 -> 其中:主营业务成本 | B12: 2114358.2 | C12: 7060951.5 | D12: 4577497.7
B13: 2418428.9 | C13: 8839205.2 | D13: 9843943.6
A14: ='[34]表I-1近年利润表'!A13 -> 其他业务成本
A15: ='[34]表I-1近年利润表'!A14 -> 营业税金及附加 | B15: 0 | C15: 19772.45 | D15: 4228.6
A16: ='[34]表I-1近年利润表'!A15 -> 营业费用 | B16: 206429.86 | C16: 159667.88 | D16: 142374.42
A17: ='[34]表I-1近年利润表'!A16 -> 管理费用 | B17: 8885053.8 | C17: 8515846.9 | D17: 5194277.1
A18: ='[34]表I-1近年利润表'!A17 -> 财务费用 | B18: -31334.51 | C18: 700.17 | D18: 2898.07
A19: ='[34]表I-1近年利润表'!A18 -> 资产减值损失 | B19: 131977.38 | C19: 173684.15 | D19: 586599.74
A20: ='[34]表I-1近年利润表'!A19 -> 加：公允价值变动收益 | B20: -72073 | C20: 72073 | D20: 0
A21: ='[34]表I-1近年利润表'!A20 -> 投资收益 | B21: 63559.56 | C21: 1832010.4 | D21: 0
A22: ='[34]表I-1近年利润表'!A21 -> 三、营业利润 | B22: =B7-B10+B20+B21 -> -8379951 | C22: =C7-C10+C20+C21 -> -3212271.9 | D22: =D7-D10+D20+D21 -> -7393699.9
A23: ='[34]表I-1近年利润表'!A22 -> 加：营业外收入 | B23: 175926.16 | C23: 10000 | D23: 1501.06
A24: ='[34]表I-1近年利润表'!A23 -> 减: 营业外支出 | B24: 0 | C24: 2.23 | D24: 35.4
A25: ='[34]表I-1近年利润表'!A24 -> 四、利润总额 | B25: =B22+B23-B24 -> -8204024.9 | C25: =C22+C23-C24 -> -3202274.1 | D25: =D22+D23-D24 -> -7392234.2
A26: ='[34]表I-1近年利润表'!A25 -> 减: 所得税 | B26: -1492947.6 | C26: -43421.04 | D26: -146649.94
A27: ='[34]表I-1近年利润表'!A26 -> 五、净利润 | B27: =B25-B26 -> -6711077.2 | C27: =C25-C26 -> -3158853.1 | D27: =D25-D26 -> -7245584.3
A28: ='[34]表I-1近年利润表'!A27 -> 净利润增长率 | C28: =IF(B27=0,"",ROUND((C27-B27)/B27,4)) -> -0.5293 | D28: =IF(C27=0,"",ROUND((D27-C27)/C27,4)) -> 1.2937
A29: ='[34]表I-1近年利润表'!A28 -> 其中：少数股东损益
A30: ='[34]表I-1近年利润表'!A29 -> 占总利润比例 | B30: =IF(B27=0,"",IF(B29<>0,B29/B27,"")) | C30: =IF(C27=0,"",IF(C29<>0,C29/C27,"")) | D30: =IF(D27=0,"",IF(D29<>0,D29/D27,""))
A31: ='[34]表I-1近年利润表'!A30 -> 六、归属于母公司损益 | B31: =B27-B29 -> -6711077.2 | C31: =C27-C29 -> -3158853.1 | D31: =D27-D29 -> -7245584.3

Sheet 财务指标分析表
A2: =封面!B2 -> 被评估单位：福建卫东新能源股份有限公司 | F2: 评估基准日： | G2: =封面!C3 -> 2017年12月31日
A4: 序号 | B4: 项目名称 \ 年份 | C4: 单位 | D4: ='[34]表I-2调整后利润表'!B6 -> 2015 | E4: ='[34]表I-2调整后利润表'!C6 -> 2016 | F4: ='[34]表I-2调整后利润表'!D6 -> 2017 | G4: 均值
A5: 1 | B5: 主营收入增长率 | C5: % | D5: —— | E5: =(利润分析调整表!C8-利润分析调整表!B8)/利润分析调整表!B8*100 -> 256.84679 | F5: =(利润分析调整表!D7-利润分析调整表!C7)/利润分析调整表!C7*100 -> -71.203083 | G5: =(E5+F5)/2 -> 92.821853
A6: 2 | B6: 主营业务毛利率 | C6: % | D6: =(利润分析调整表!B8-利润分析调整表!B12)/利润分析调整表!B8*100 -> 27.961695 | E6: =(利润分析调整表!C8-利润分析调整表!C12)/利润分析调整表!C8*100 -> 32.583477 | F6: =(利润分析调整表!D8-利润分析调整表!D12)/利润分析调整表!D8*100 -> -46.989062 | G6: =(D6+E6+F6)/3 -> 4.5187033
A7: 3 | B7: 其他业务毛利率 | C7: % | D7: —— | E7: =(利润分析调整表!C9-利润分析调整表!C14)/利润分析调整表!C9*100 -> 100 | F7: =(利润分析调整表!D9-利润分析调整表!D14)/利润分析调整表!D9*100 -> #DIV/0!
A8: 4 | B8: 营业税金比率 | C8: % | D8: =利润分析调整表!B15/利润分析调整表!B7*100 -> 0 | E8: =利润分析调整表!C15/利润分析调整表!C7*100 -> 0.1828367 | F8: =利润分析调整表!D15/利润分析调整表!D7*100 -> 0.13578553 | G8: =(D8+E8+F8)/3 -> 0.10620741
A9: 5 | B9: 营业费用比率 | C9: % | D9: =利润分析调整表!B16/利润分析调整表!B7*100 -> 7.0332724 | E9: =利润分析调整表!C16/利润分析调整表!C7*100 -> 1.4764558 | F9: =利润分析调整表!D16/利润分析调整表!D7*100 -> 4.5718172 | G9: =(D9+E9+F9)/3 -> 4.3605151
A10: 6 | B10: 管理费用比率 | C10: % | D10: =利润分析调整表!B17/利润分析调整表!B7*100 -> 302.72269 | E10: =利润分析调整表!C17/利润分析调整表!C7*100 -> 78.746404 | F10: =利润分析调整表!D17/利润分析调整表!D7*100 -> 166.79461 | G10: =(D10+E10+F10)/3 -> 182.75457
A11: 7 | B11: 财务费用比率 | C11: % | D11: =利润分析调整表!B18/利润分析调整表!B7*100 -> -1.0675982 | E11: =利润分析调整表!C18/利润分析调整表!C7*100 -> 0.0064745021 | F11: =利润分析调整表!D18/利润分析调整表!D7*100 -> 0.093060581 | G11: =(D11+E11+F11)/3 -> -0.3226877
A12: 8 | B12: 投资收益比率 | C12: % | D12: =利润分析调整表!B21/利润分析调整表!B7*100 -> 2.165538 | E12: =利润分析调整表!C21/利润分析调整表!C7*100 -> 16.940679 | F12: =利润分析调整表!D21/利润分析调整表!D7*100 -> 0 | G12: =(D12+E12+F12)/3 -> 6.3687389
A13: 9 | B13: 营业利润比率 | C13: % | D13: =利润分析调整表!B22/利润分析调整表!B7*100 -> -285.51334 | E13: =利润分析调整表!C22/利润分析调整表!C7*100 -> -29.704017 | F13: =利润分析调整表!D22/利润分析调整表!D7*100 -> -237.42077 | G13: =(D13+E13+F13)/3 -> -184.21271
A14: 10 | B14: 营业外收入比率 | C14: % | D14: =利润分析调整表!B23/利润分析调整表!B7*100 -> 5.9939807 | E14: =利润分析调整表!C23/利润分析调整表!C7*100 -> 0.092470431 | F14: =利润分析调整表!D23/利润分析调整表!D7*100 -> 0.048200877 | G14: =(D14+E14+F14)/3 -> 2.044884
A15: 11 | B15: 营业外支出比率 | C15: % | D15: =利润分析调整表!B24/利润分析调整表!B7*100 -> 0 | E15: =利润分析调整表!C24/利润分析调整表!C7*100 -> 2.0620906e-05 | F15: =利润分析调整表!D24/利润分析调整表!D7*100 -> 0.0011367374 | G15: =(D15+E15+F15)/3 -> 0.0003857861
A16: 一、 | B16: 营运能力
A17: 1 | B17: 存货周转率 | C17: 次 | D17: =利润分析调整表!B11/资产负债分析调整表!C16 -> 0.61060409 | E17: =利润分析调整表!C11/((资产负债分析调整表!C16+资产负债分析调整表!D16)/2) -> 2.2981836 | F17: =利润分析调整表!B12/((资产负债分析调整表!D16+资产负债分析调整表!E16)/2) -> 0.52951752 | G17: =360/(30) -> 12 | H17: 企业以销定产，存货的生产周期为30天
A18: 2 | B18: 应收账款周转率 | C18: 次 | D18: =利润分析调整表!B7/资产负债分析调整表!C12 -> 0.8529996 | E18: =利润分析调整表!C7/((资产负债分析调整表!C12+资产负债分析调整表!D12)/2) -> 1.7655674 | F18: =利润分析调整表!D7/((资产负债分析调整表!D12+资产负债分析调整表!E12)/2) -> 0.51605476 | G18: =360/30 -> 12 | H18: 交货后的收款周期为30天,一般预收为20%，应收则80%
B19: 预付账款周转率 | C19: 次 | D19: =利润分析调整表!B11/资产负债分析调整表!C14 -> 0.48649737 | E19: =利润分析调整表!C11/((资产负债分析调整表!D14+资产负债分析调整表!C14)/2) -> 2.6935773 | F19: =利润分析调整表!D11/((资产负债分析调整表!E14+资产负债分析调整表!D14)/2) -> 2.8805909 | G19: =360/30 -> 12 | H19: 企业预付款后一般30天可以提货，预付款约20%
A20: 3 | B20: 流动资产周转率 | C20: 次 | D20: =利润分析调整表!B7/资产负债分析调整表!C6 -> 0.035312384 | E20: =利润分析调整表!C7/((资产负债分析调整表!C6+资产负债分析调整表!D6)/2) -> 0.13535612 | F20: =利润分析调整表!D7/((资产负债分析调整表!D6+资产负债分析调整表!E6)/2) -> 0.04228818 | G20: =(D20+E20+F20)/3 -> 0.070985561
A21: 4 | B21: 资产周转率 | C21: 次 | D21: =利润分析调整表!B7/资产负债分析调整表!C43 -> 0.028626616 | E21: =利润分析调整表!C7/((资产负债分析调整表!C43+资产负债分析调整表!D43)/2) -> 0.100801 | F21: =利润分析调整表!D7/((资产负债分析调整表!D43+资产负债分析调整表!E43)/2) -> 0.028659439 | G21: =(D21+E21+F21)/3 -> 0.052695684
B22: 应付账款周转率 | C22: 次 | D22: =利润分析调整表!B12/资产负债分析调整表!C48 -> 5.6694944 | E22: =利润分析调整表!C12/((资产负债分析调整表!C48+资产负债分析调整表!D48)/2) -> 5.9506362 | F22: =利润分析调整表!D11/((资产负债分析调整表!D48+资产负债分析调整表!E48)/2) -> 2.2804032 | G22: =360/30 -> 12 | H22: 提货后一般一个月内付款，应付款一般比例为80%
B23: 预收账款周转率 | C23: 次 | E23: =利润分析调整表!C8/((资产负债分析调整表!C49+资产负债分析调整表!D49)/1) -> 173.3541 | F23: =利润分析调整表!D8/((资产负债分析调整表!D49+资产负债分析调整表!E49)/1) -> 10.350462 | G23: =360/60 -> 6 | H23: 付款后至提货时间一般为30天，加上采购时间30天。预收比例为20%
A25: 二、 | B25: 短期偿债能力
A26: 1 | B26: 流动比率 | D26: =资产负债分析调整表!C6/资产负债分析调整表!C44 -> -35.822459 | E26: =资产负债分析调整表!D6/((资产负债分析调整表!D44+资产负债分析调整表!C44)/2) -> 18.469771 | F26: =资产负债分析调整表!E6/((资产负债分析调整表!E44+资产负债分析调整表!D44)/2) -> 6.496513 | G26: =(D26+E26+F26)/3 -> -3.6187249
A27: 2 | B27: 速动比率 | D27: =(资产负债分析调整表!C6-资产负债分析调整表!C16)/资产负债分析调整表!C44 -> -34.330055 | E27: =(资产负债分析调整表!D6-资产负债分析调整表!D16)/((资产负债分析调整表!D44+资产负债分析调整表!C44)/2) -> 17.823686 | F27: =(资产负债分析调整表!E6-资产负债分析调整表!E16)/((资产负债分析调整表!E44+资产负债分析调整表!D44)/2) -> 6.0085265 | G27: =(D27+E27+F27)/3 -> -3.4992808
A28: 三、 | B28: 长期偿债能力
A29: 1 | B29: 资产负债率 | C29: % | D29: =资产负债分析调整表!C66/资产负债分析调整表!C43*100 -> -2.2630157 | E29: =资产负债分析调整表!D66/((资产负债分析调整表!D43+资产负债分析调整表!C43)/2)*100 -> 9.9016312 | F29: =资产负债分析调整表!E66/((资产负债分析调整表!E43+资产负债分析调整表!D43)/2)*100 -> 10.229116 | G29: =(D29+E29+F29)/3 -> 5.9559106
A30: 2 | B30: 负债与股权比率 | C30: % | D30: =资产负债分析调整表!C66/资产负债分析调整表!C67*100 -> -2.2129366 | E30: =资产负债分析调整表!D66/((资产负债分析调整表!C67+资产负债分析调整表!D67)/2)*100 -> 10.300193 | F30: =资产负债分析调整表!E66/((资产负债分析调整表!D67+资产负债分析调整表!E67)/2)*100 -> 11.366011 | G30: =(D30+E30+F30)/3 -> 6.4844224
A31: 四、 | B31: 获利能力
A32: 1 | B32: 销售净利率 | C32: % | D32: =利润分析调整表!B25/利润分析调整表!B7*100 -> -279.51936 | E32: =利润分析调整表!C25/利润分析调整表!C7*100 -> -29.611567 | F32: =利润分析调整表!D25/利润分析调整表!D7*100 -> -237.3737 | G32: =(D32+E32+F32)/3 -> -182.16821
A33: 2 | B33: 资产净利率 | C33: % | D33: =利润分析调整表!B27/资产负债分析调整表!C43*100 -> -6.5455653 | E33: =利润分析调整表!C27/((资产负债分析调整表!C43+资产负债分析调整表!D43)/2)*100 -> -2.9444022 | F33: =利润分析调整表!D27/((资产负债分析调整表!D43+资产负债分析调整表!E43)/2)*100 -> -6.6680368 | G33: =(D33+E33+F33)/3 -> -5.3860014
A34: 3 | B34: 成本费用利润率 | C34: % | D34: =利润分析调整表!B25/利润分析调整表!B10*100 -> -72.56035 | E34: =利润分析调整表!C25/利润分析调整表!C10*100 -> -20.101374 | F34: =利润分析调整表!D25/利润分析调整表!D10*100 -> -70.349465 | G34: =(D34+E34+F34)/3 -> -54.337063
A35: 4 | B35: 净资产收益率 | C35: % | D35: =利润分析调整表!B27/资产负债分析调整表!C67*100 -> -6.4007161 | E35: =(利润分析调整表!C27/(资产负债分析调整表!C67+资产负债分析调整表!D67)/2)*100 -> -0.76573013 | F35: =(利润分析调整表!D27/(资产负债分析调整表!D67+资产负债分析调整表!E67)/2)*100 -> -1.8522856 | G35: =(D35+E35+F35)/3 -> -3.006244
B36: 注：运营能力的周转率指标，分母采用期初和期末的均值计算。

Sheet 财务指标详表
A2: =封面!B2 -> 被评估单位：福建卫东新能源股份有限公司 | E2: 评估基准日： | F2: =封面!C3 -> 2017年12月31日
A4: 一、资产负债结构分析
A5: 1.资产结构及变化分析
A6: 序号 | B6: 项目名称 | C6: =资产负债分析调整表!C4 -> 2015年12月31日 | E6: =资产负债分析调整表!D4 -> 2016年12月31日 | G6: =资产负债分析调整表!E4 -> 2017年12月31日
C7: 金额（万元） | D7: 比例% | E7: 金额（万元） | F7: 比例% | G7: 金额（万元） | H7: 比例%
A8: 1 | B8: 流动资产 | C8: =资产负债分析调整表!C6/10000 -> 8311.6651 | D8: =C8/C$10 -> 0.81066787 | E8: =资产负债分析调整表!D6/10000 -> 7667.3213 | F8: =E8/E$10 -> 0.68434962 | G8: =资产负债分析调整表!E6/10000 -> 7061.0292 | H8: =G8/G$10 -> 0.67065994
A9: 2 | B9: 非流动资产 | C9: =资产负债分析调整表!C20/10000 -> 1941.196 | D9: =C9/C$10 -> 0.18933213 | E9: =资产负债分析调整表!D20/10000 -> 3536.486 | F9: =E9/E$10 -> 0.31565038 | G9: =资产负债分析调整表!E20/10000 -> 3467.45 | H9: =G9/G$10 -> 0.32934006
A10: 3 | B10: 合计 | C10: =SUM(C8:C9) -> 10252.861 | D10: =C10/C$10 -> 1 | E10: =SUM(E8:E9) -> 11203.807 | F10: =E10/E$10 -> 1 | G10: =SUM(G8:G9) -> 10528.479 | H10: =G10/G$10 -> 1
A12: 2.流动资产结构及变化分析
A13: 序号 | B13: 项目名称 | C13: =C6 -> 2015年12月31日 | E13: =E6 -> 2016年12月31日 | G13: =G6 -> 2017年12月31日
C14: 金额（万元） | D14: 比例% | E14: 金额（万元） | F14: 比例% | G14: 金额（万元） | H14: 比例%
A15: 1 | B15: ='[34]表I-3资产负债分析调整表'!B7 -> 货币资金 | C15: =资产负债分析调整表!C7/10000 -> 662.84143 | D15: =IF(C$28=0,0,C15/C$28) -> 0.079748332 | E15: =资产负债分析调整表!D7/10000 -> 11.747661 | F15: =IF(E$28=0,0,E15/E$28) -> 0.0015321728 | G15: =资产负债分析调整表!E7/10000 -> 6.408064 | H15: =IF(G$28=0,0,G15/G$28) -> 0.00090752549
A16: 2 | B16: ='[34]表I-3资产负债分析调整表'!B8 -> 交易性金融资产净额 | C16: =资产负债分析调整表!C8/10000 -> 61.9575 | D16: =IF(C$28=0,0,C16/C$28) -> 0.0074542825 | E16: =资产负债分析调整表!D8/10000 -> 0 | F16: =IF(E$28=0,0,E16/E$28) -> 0 | G16: =资产负债分析调整表!E8/10000 -> 0 | H16: =IF(G$28=0,0,G16/G$28) -> 0
A17: 3 | B17: ='[34]表I-3资产负债分析调整表'!B9 -> 应收票据 | C17: =资产负债分析调整表!C9/10000 -> 0 | D17: =IF(C$28=0,0,C17/C$28) -> 0 | E17: =资产负债分析调整表!D9/10000 -> 190 | F17: =IF(E$28=0,0,E17/E$28) -> 0.024780493 | G17: =资产负债分析调整表!E9/10000 -> 0 | H17: =IF(G$28=0,0,G17/G$28) -> 0
A18: 4 | B18: ='[34]表I-3资产负债分析调整表'!B10 -> 应收股利(应收利润) | C18: =资产负债分析调整表!C10/10000 -> 0 | D18: =IF(C$28=0,0,C18/C$28) -> 0 | E18: =资产负债分析调整表!D10/10000 -> 0 | F18: =IF(E$28=0,0,E18/E$28) -> 0 | G18: =资产负债分析调整表!E10/10000 -> 0 | H18: =IF(G$28=0,0,G18/G$28) -> 0
A19: 5 | B19: ='[34]表I-3资产负债分析调整表'!B11 -> 应收利息 | C19: =资产负债分析调整表!C11/10000 -> 0 | D19: =IF(C$28=0,0,C19/C$28) -> 0 | E19: =资产负债分析调整表!D11/10000 -> 0 | F19: =IF(E$28=0,0,E19/E$28) -> 0 | G19: =资产负债分析调整表!E11/10000 -> 0 | H19: =IF(G$28=0,0,G19/G$28) -> 0
A20: 6 | B20: ='[34]表I-3资产负债分析调整表'!B12 -> 应收账款净额 | C20: =资产负债分析调整表!C12/10000 -> 344.08541 | D20: =IF(C$28=0,0,C20/C$28) -> 0.041397891 | E20: =资产负债分析调整表!D12/10000 -> 880.93359 | F20: =IF(E$28=0,0,E20/E$28) -> 0.11489457 | G20: =资产负债分析调整表!E12/10000 -> 325.98318 | H20: =IF(G$28=0,0,G20/G$28) -> 0.046166525
A21: 7 | B21: ='[34]表I-3资产负债分析调整表'!B13 -> 其他应收款净额 | C21: =资产负债分析调整表!C13/10000 -> 6461.8993 | D21: =IF(C$28=0,0,C21/C$28) -> 0.77744942 | E21: =资产负债分析调整表!D13/10000 -> 6226.7599 | F21: =IF(E$28=0,0,E21/E$28) -> 0.81211674 | G21: =资产负债分析调整表!E13/10000 -> 5970.1035 | H21: =IF(G$28=0,0,G21/G$28) -> 0.84550046
A22: 8 | B22: ='[34]表I-3资产负债分析调整表'!B14 -> 预付帐款 | C22: =资产负债分析调整表!C14/10000 -> 434.60836 | D22: =IF(C$28=0,0,C22/C$28) -> 0.052288963 | E22: =资产负债分析调整表!D14/10000 -> 89.672235 | F22: =IF(E$28=0,0,E22/E$28) -> 0.01169538 | G22: =资产负债分析调整表!E14/10000 -> 228.14434 | H22: =IF(G$28=0,0,G22/G$28) -> 0.032310352
A23: 9 | B23: ='[34]表I-3资产负债分析调整表'!B15 -> 应收补贴款 | C23: =资产负债分析调整表!C15/10000 -> 0 | D23: =IF(C$28=0,0,C23/C$28) -> 0 | E23: =资产负债分析调整表!D15/10000 -> 0 | F23: =IF(E$28=0,0,E23/E$28) -> 0 | G23: =资产负债分析调整表!E15/10000 -> 0 | H23: =IF(G$28=0,0,G23/G$28) -> 0
A24: 10 | B24: ='[34]表I-3资产负债分析调整表'!B16 -> 存货净额 | C24: =资产负债分析调整表!C16/10000 -> 346.27318 | D24: =IF(C$28=0,0,C24/C$28) -> 0.041661108 | E24: =资产负债分析调整表!D16/10000 -> 268.20787 | F24: =IF(E$28=0,0,E24/E$28) -> 0.034980649 | G24: =资产负债分析调整表!E16/10000 -> 530.39016 | H24: =IF(G$28=0,0,G24/G$28) -> 0.075115134
A25: 11 | B25: ='[34]表I-3资产负债分析调整表'!B17 -> 待摊费用 | C25: =资产负债分析调整表!C17/10000 -> 0 | D25: =IF(C$28=0,0,C25/C$28) -> 0 | E25: =资产负债分析调整表!D17/10000 -> 0 | F25: =IF(E$28=0,0,E25/E$28) -> 0 | G25: =资产负债分析调整表!E17/10000 -> 0 | H25: =IF(G$28=0,0,G25/G$28) -> 0
A26: 12 | B26: ='[34]表I-3资产负债分析调整表'!B18 -> 一年内到期的非流动资产 | C26: =资产负债分析调整表!C18/10000 -> 0 | D26: =IF(C$28=0,0,C26/C$28) -> 0 | E26: =资产负债分析调整表!D18/10000 -> 0 | F26: =IF(E$28=0,0,E26/E$28) -> 0 | G26: =资产负债分析调整表!E18
A27: 13 | B27: ='[34]表I-3资产负债分析调整表'!B19 -> 其他流动资产 | C27: =资产负债分析调整表!C19/10000 -> 0 | D27: =IF(C$28=0,0,C27/C$28) -> 0 | E27: =资产负债分析调整表!D19/10000 -> 0 | F27: =IF(E$28=0,0,E27/E$28) -> 0 | G27: =资产负债分析调整表!E19 -> 0 | H27: =IF(G$28=0,0,G27/G$28) -> 0
A28: 14 | B28: 合计 | C28: =SUM(C15:C27) -> 8311.6651 | D28: =SUM(D15:D27) -> 1 | E28: =SUM(E15:E27) -> 7667.3213 | F28: =SUM(F15:F27) -> 1 | G28: =SUM(G15:G27) -> 7061.0292 | H28: =SUM(H15:H27) -> 1
A30: 3.应收账款分析
A31: 序号 | B31: 账龄 | C31: =C13 -> 2015年12月31日
C32: 账面原值（万元） | D32: 比例 | E32: 坏账准备（万元） | F32: 计提比例 | G32: 账面净值（万元）
A33: 1 | B33: 1年以内 | C33: 356434.06 | D33: =IF(C$37=0,0,C33/C$37) -> 0.096557398 | F33: =IF(C33=0,0,ROUND(E33/C33,3)) -> 0 | G33: =C33-E33 -> 356434.06
A34: 2 | B34: 1～2年 | C34: 3322387.5 | D34: =IF(C$37=0,0,C34/C$37) -> 0.90002928 | F34: =IF(C34=0,0,ROUND(E34/C34,3)) -> 0 | G34: =C34-E34 -> 3322387.5
A35: 3 | B35: 2～3年 | D35: =IF(C$37=0,0,C35/C$37) -> 0 | F35: =IF(C35=0,0,ROUND(E35/C35,3)) -> 0 | G35: =C35-E35 -> 0
A36: 4 | B36: 3年以上 | C36: 12600 | D36: =IF(C$37=0,0,C36/C$37) -> 0.0034133192 | F36: =IF(C36=0,0,ROUND(E36/C36,3)) -> 0 | G36: =C36-E36 -> 12600
A37: 5 | B37: 合计 | C37: =SUM(C33:C36) -> 3691421.6 | D37: =IF(C$37=0,0,C37/C$37) -> 1 | E37: =SUM(E33:E36) -> 0 | G37: =C37-E37 -> 3691421.6
A39: 序号 | B39: 账龄 | C39: =E6 -> 2016年12月31日
C40: 账面原值（万元） | D40: 比例 | E40: 坏账准备（万元） | F40: 计提比例 | G40: 账面净值（万元）
A41: 1 | B41: 1年以内 | C41: 1430.0284 | D41: =IF(C$45=0,0,C41/C$45) -> 0.99982129 | E41: 71.50142 | F41: =IF(C41=0,0,ROUND(E41/C41,3)) -> 0.05 | G41: =C41-E41 -> 1358.527
A42: 2 | B42: 1～2年 | C42: 0 | D42: =IF(C$45=0,0,C42/C$45) -> 0 | F42: =IF(C42=0,0,ROUND(E42/C42,3)) -> 0 | G42: =C42-E42 -> 0
A43: 3 | B43: 2～3年 | C43: 0.2556 | D43: =IF(C$45=0,0,C43/C$45) -> 0.00017870577 | E43: 0.07668 | F43: =IF(C43=0,0,ROUND(E43/C43,3)) -> 0.3 | G43: =C43-E43 -> 0.17892
A44: 4 | B44: 3年以上 | D44: =IF(C$45=0,0,C44/C$45) -> 0 | F44: =IF(C44=0,0,ROUND(E44/C44,3)) -> 0 | G44: =C44-E44 -> 0
A45: 5 | B45: 合计 | C45: =SUM(C41:C44) -> 1430.284 | D45: =IF(C$45=0,0,C45/C$45) -> 1 | E45: =SUM(E41:E44) -> 71.5781 | G45: =C45-E45 -> 1358.7059
...

Sheet 收入--历史经营情况分析
B2: 项目 | C2: 2017 年 | E2: 2016年 | G2: 2015 年
C3: 金额 | D3: 比例 | E3: 金额 | F3: 比例 | G3: 金额 | H3: 比例
B4: 一、产品销售收入 | C4: =SUM(C5:C9) -> 216.72 | D4: =C4/C11 -> 0.69591326 | E4: =SUM(E5:E9) -> 717.95 | F4: =E4/E11 -> 0.68548524 | G4: =SUM(G5:G9) -> 221.83 | H4: =G4/G11 -> 0.75579463
B5: 其中： 镍氢电池组 | C5: 92.48 | D5: =C5/$C$4 -> 0.42672573 | E5: 15.77 | F5: =E5/$E$4 -> 0.021965318 | G5: 57.73 | H5: =G5/$G$4 -> 0.26024433
B6: 镍氢电池单体 | C6: 0.41 | D6: =C6/$C$4 -> 0.001891842 | E6: 0 | F6: =E6/$E$4 -> 0 | G6: 164.1 | H6: =G6/$G$4 -> 0.73975567
B7: 镍氢动力电池系统 | C7: 120.11 | D7: =C7/$C$4 -> 0.55421742 | E7: 692.31 | F7: =E7/$E$4 -> 0.96428721 | G7: 0 | H7: =G7/$G$4 -> 0
B8: 镍氢动力电池正负极板 | C8: 3.72 | D8: =C8/$C$4 -> 0.017165006 | E8: 9.87 | F8: =E8/$E$4 -> 0.013747475 | G8: 0 | H8: =G8/$G$4 -> 0
B9: 镍氢电池生产设备 | C9: 0 | D9: =C9/$C$4 -> 0 | E9: 0 | F9: =E9/$E$4 -> 0 | G9: 0 | H9: =G9/$G$4 -> 0
B10: 二、材料销售收入 | C10: =946981.23/10000 -> 94.698123 | D10: =C10/C11 -> 0.30408674 | E10: =3294102.57/10000 -> 329.41026 | F10: =E10/E11 -> 0.31451476 | G10: =716756.56/10000 -> 71.675656 | H10: =G10/G11 -> 0.24420537
B11: 收入合计 | C11: =C4+C10 -> 311.41812 | D11: =D4+D10 -> 1 | E11: =E4+E10 -> 1047.3603 | F11: =F4+F10 -> 1 | G11: =G4+G10 -> 293.50566 | H11: =H4+H10 -> 1

Sheet 收入--2018年收入分析表
A1: 一、主要管理者的访谈 | B1: 根据访谈情况：卫东新能源公司实行“以销定产”的经营模式，而15年到17年由于处于对购买的非专利技术进行吸收改进创新阶段，未能大规模地投入量产，且产品处于初投入市场状态，销售未达到预期，产能未能满负荷生产，造成各项经营数据都不正常。2018年随着公司销售渠道的拓展，生产电池生产设备及电池组及配件等让其销售收入有了大幅的增加。随着卫东新能源公司销售的拓展，各种盈利能力、营运能力指标将逐渐向良性方向发展。
A2: 二、截至现场勘查日已签订的销售合同
A3: 1、合同情况 | B3: 根据统计，截至现场勘查日，被评估企业已经签订的销售合同有8份（其中2份为同一客户），合同总金额为3218.26万元。
A11: 2、主要合同访谈分析情况 | B11: 福建翰飞新能源科技有限公司
B12: 同创精密自动化设备有限公司
A13: 3、登记的合同统计分析 | B13: 项目 | C13: 合同金额（不含税）
B14: 镍氢电池组 | C14: 3.67
B15: 镍氢电池单体 | C15: 328.13
B16: 镍氢动力电池系统 | C16: 218.8
B17: 镍氢动力电池正负极板 | C17: 1039.32
B18: 镍氢电池生产设备 | C18: 1161.25
B19: 收入合计 | C19: 2751.17

Sheet 收入预测表
D2: 0.2 | E2: 0.18 | F2: 0.15 | G2: 0.1 | H2: 0
B3: 产品品称 | C3: 2018年 | D3: 2019年 | E3: 2020年 | F3: 2021年 | G3: 2022年 | H3: 2023年及以后
B4: 镍氢电池组 | C4: ='收入--2018年收入分析表'!C14 -> 3.67 | D4: =C4*(1+$D$2) -> 4.404 | E4: =D4*(1+$E$2) -> 5.19672 | F4: =E4*(1+$F$2) -> 5.976228 | G4: =F4*(1+$G$2) -> 6.5738508 | H4: =G4*(1+$H$2) -> 6.5738508
B5: 镍氢电池单体 | C5: ='收入--2018年收入分析表'!C15 -> 328.13 | D5: =C5*(1+$D$2) -> 393.756 | E5: =D5*(1+$E$2) -> 464.63208 | F5: =E5*(1+$F$2) -> 534.32689 | G5: =F5*(1+$G$2) -> 587.75958 | H5: =G5*(1+$H$2) -> 587.75958
B6: 镍氢动力电池系统 | C6: ='收入--2018年收入分析表'!C16 -> 218.8 | D6: =C6*(1+$D$2) -> 262.56 | E6: =D6*(1+$E$2) -> 309.8208 | F6: =E6*(1+$F$2) -> 356.29392 | G6: =F6*(1+$G$2) -> 391.92331 | H6: =G6*(1+$H$2) -> 391.92331
B7: 镍氢动力电池正负极板 | C7: ='收入--2018年收入分析表'!C17 -> 1039.32 | D7: =C7*(1+$D$2) -> 1247.184 | E7: =D7*(1+$E$2) -> 1471.6771 | F7: =E7*(1+$F$2) -> 1692.4287 | G7: =F7*(1+$G$2) -> 1861.6716 | H7: =G7*(1+$H$2) -> 1861.6716
B8: 镍氢电池生产设备 | C8: ='收入--2018年收入分析表'!C18 -> 1161.25 | D8: =C8*(1+$D$2) -> 1393.5 | E8: =D8*(1+$E$2) -> 1644.33 | F8: =E8*(1+$F$2) -> 1890.9795 | G8: =F8*(1+$G$2) -> 2080.0775 | H8: =G8*(1+$H$2) -> 2080.0775
B9: 合 计 | C9: =SUM(C4:C8) -> 2751.17 | D9: =SUM(D4:D8) -> 3301.404 | E9: =SUM(E4:E8) -> 3895.6567 | F9: =SUM(F4:F8) -> 4480.0052 | G9: =SUM(G4:G8) -> 4928.0058 | H9: =SUM(H4:H8) -> 4928.0058

Sheet 成本--成本比例分析
A3: 一、历史数据分析
B5: 项目内容 | C5: 2015年 | D5: 2016年 | E5: 2017年
A6: 镍氢电池组 | B6: 收入 | C6: ='收入--历史经营情况分析'!G5 -> 57.73 | D6: ='收入--历史经营情况分析'!E5 -> 15.77 | E6: ='收入--历史经营情况分析'!C5 -> 92.48
B7: 成本 | C7: =395108.82/10000 -> 39.510882 | D7: =250700.6/10000 -> 25.07006 | E7: =2688733.16/10000 -> 268.87332
B8: 成本收入占比 | C8: =C7/C6 -> 0.68440814 | D8: =D7/D6 -> 1.5897311 | E8: =E7/E6 -> 2.9073672
A9: 镍氢电池单体 | B9: 收入 | C9: ='收入--历史经营情况分析'!G6 -> 164.1 | D9: ='收入--历史经营情况分析'!E6 -> 0 | E9: ='收入--历史经营情况分析'!C6 -> 0.41
B10: 成本 | C10: =1023950.68/10000 -> 102.39507 | E10: =9077.54/10000 -> 0.907754
B11: 成本收入占比 | C11: =C10/C9 -> 0.6239797 | E11: =E10/E9 -> 2.2140341
A12: 镍氢动力电池系统 | B12: 收入 | C12: ='收入--历史经营情况分析'!G7 -> 0 | D12: ='收入--历史经营情况分析'!E7 -> 692.31 | E12: ='收入--历史经营情况分析'!C7 -> 120.11
B13: 成本 | D13: =4463888.7/10000 -> 446.38887 | E13: =931465.8/10000 -> 93.14658
B14: 成本收入占比 | D14: =D13/D12 -> 0.64478177 | E14: =E13/E12 -> 0.77551062
A15: 镍氢动力电池正负极板 | B15: 收入 | C15: ='收入--历史经营情况分析'!G8 -> 0 | D15: ='收入--历史经营情况分析'!E8 -> 9.87 | E15: ='收入--历史经营情况分析'!C8 -> 3.72
B16: 成本 | D16: =352163.16/10000 -> 35.216316 | E16: =86580.89/10000 -> 8.658089
B17: 成本收入占比 | D17: =D16/D15 -> 3.5680158 | E17: =E16/E15 -> 2.3274433
A18: 镍氢电池生产设备 | B18: 收入
B19: 成本
B20: 成本收入占比
A21: 材料 | B21: 收入 | C21: ='收入--历史经营情况分析'!G10 -> 71.675656 | D21: ='收入--历史经营情况分析'!E10 -> 329.41026 | E21: ='收入--历史经营情况分析'!C10 -> 94.698123
B22: 成本 | C22: 69.53 | D22: 199.42 | E22: 86.16
B23: 成本收入占比
A24: 产品成本合计 | C24: =C7+C10+C13+C16+C19+C22 -> 211.43595 | D24: =D7+D10+D13+D16+D19+D22 -> 706.09525 | E24: =E7+E10+E13+E16+E19+E22 -> 457.74574
A25: 收入合计 | C25: =C6+C9+C12+C15+C18+C21 -> 293.50566 | D25: =D6+D9+D12+D15+D18+D21 -> 1047.3603 | E25: =E6+E9+E12+E15+E18+E21 -> 311.41812
A26: 总成本占主总收入比例 | C26: 0.7204 | D26: 0.6742 | E26: 1.4699
G28: 成本占比
A29: 分析： | B29: 2015年-2017年卫东新能源的生产不足产能的10%，在成本核算上固定成本相对较高，造成单位成本偏高，甚至出现成本倒挂的现象。特别是2017年的营业收入偏低，其中的折旧费跟制造费用则按照实际发生列支，造成2017年的营业成本占营业收入的比例超高，而2015年-2016年的总成本与主营业务收入的比例属于比较正常的范围，在这二年，产能也不未充分发挥。 | F29: 分析结论：17年数据差异较大，若剔除17年因素，采用15、16年的经营数据平均值综合考虑，成本占收入的比率约为70%。 | G29: 0.7
A32: 二、行业数据分析
A34: 通过万得数据查找类似上市公司的经营数据，评估人员发现电池产品的平均销售毛利大部分位于12%~20%区间，
A38: 600478
A40: 镍
A51: 300068
A52: 锂电池
A62: 300438
A74: 000049
A76: 锂电池
A84: 002580
A86: 阀控密封式铅酸蓄电池
A97: 300207
A99: 锂离子电池
B112: 上市公司名称 | C112: 编号 | D112: 主营产品 | E112: 近4期平均毛利率
B113: 科力远 | C113: 600478 | D113: 电池占比45.52% | E113: 0.1033
...

Sheet 主要材料情况
D3: 厂家 | E3: 产量 | F3: 采购单价
F4: 2016（7-12） | G4: 2017 | H4: 2018 | I4: 2019 | J4: 2020 | K4: 2021 | L4: 2022 | M4: 2023 | N4: 2024 | O4: 2025 | P4: 2026-2039 | Q4: 2040 | R4: 2041-2043 | S4: 2044 | T4: 2045-2048 | U4: 2049-2051
C5: 药剂PAM | F5: =$V$5*'收入--历史经营情况分析'!#REF! -> #REF! | G5: =$V$5*'收入--历史经营情况分析'!#REF! -> #REF! | H5: =$V$5*'收入--历史经营情况分析'!#REF! -> #REF! | I5: =$V$5*'收入--历史经营情况分析'!#REF! -> #REF! | J5: =$V$5*'收入--历史经营情况分析'!#REF! -> #REF! | K5: =$V$5*'收入--历史经营情况分析'!#REF! -> #REF! | L5: =$V$5*'收入--历史经营情况分析'!#REF! -> #REF! | M5: =$V$5*'收入--历史经营情况分析'!#REF! -> #REF! | ... U5: =$V$5*'收入--历史经营情况分析'!#REF! -> #REF! | V5: 0.003 | W5: 吨
C6: 单价 | F6: =$V$6 -> 12000 | G6: =$V$6 -> 12000 | H6: =$V$6 -> 12000 | I6: =$V$6 -> 12000 | J6: =$V$6 -> 12000 | K6: =$V$6 -> 12000 | L6: =$V$6 -> 12000 | M6: =$V$6 -> 12000 | ... U6: =$V$6 -> 12000 | V6: 12000 | W6: 元/吨
C7: 药剂PAC | F7: =ROUND($V$7*'收入--历史经营情况分析'!#REF!,2) -> #REF! | G7: =ROUND($V$7*'收入--历史经营情况分析'!#REF!,2) -> #REF! | H7: =ROUND($V$7*'收入--历史经营情况分析'!#REF!,2) -> #REF! | I7: =ROUND($V$7*'收入--历史经营情况分析'!#REF!,2) -> #REF! | J7: =ROUND($V$7*'收入--历史经营情况分析'!#REF!,2) -> #REF! | K7: =ROUND($V$7*'收入--历史经营情况分析'!#REF!,2) -> #REF! | L7: =ROUND($V$7*'收入--历史经营情况分析'!#REF!,2) -> #REF! | M7: =ROUND($V$7*'收入--历史经营情况分析'!#REF!,2) -> #REF! | ... U7: =ROUND($V$7*'收入--历史经营情况分析'!#REF!,2) -> #REF! | V7: 0.03 | W7: 吨
C8: 药剂单价 | F8: =$V$8 -> 1700 | G8: =$V$8 -> 1700 | H8: =$V$8 -> 1700 | I8: =$V$8 -> 1700 | J8: =$V$8 -> 1700 | K8: =$V$8 -> 1700 | L8: =$V$8 -> 1700 | M8: =$V$8 -> 1700 | ... U8: =$V$8 -> 1700 | V8: 1700 | W8: 元/吨
C9: 药剂费用 | F9: =ROUND((F5*F6+F7*F8)/10000,2) -> #REF! | G9: =ROUND((G5*G6+G7*G8)/10000,2) -> #REF! | H9: =ROUND((H5*H6+H7*H8)/10000,2) -> #REF! | I9: =ROUND((I5*I6+I7*I8)/10000,2) -> #REF! | J9: =ROUND((J5*J6+J7*J8)/10000,2) -> #REF! | K9: =ROUND((K5*K6+K7*K8)/10000,2) -> #REF! | L9: =ROUND((L5*L6+L7*L8)/10000,2) -> #REF! | M9: =ROUND((M5*M6+M7*M8)/10000,2) -> #REF! | ... U9: =ROUND((U5*U6+U7*U8)/10000,2) -> #REF!
C10: 其他材料 | F10: =ROUND(F7*$O$10,2) -> #REF! | G10: =ROUND(G7*$O$10,2) -> #REF! | H10: =ROUND(H7*$O$10,2) -> #REF! | I10: =ROUND(I7*$O$10,2) -> #REF! | J10: =ROUND(J7*$O$10,2) -> #REF! | K10: =ROUND(K7*$O$10,2) -> #REF! | L10: =ROUND(L7*$O$10,2) -> #REF! | M10: =ROUND(M7*$O$10,2) -> #REF! | N10: =ROUND(N7*$O$10,2) -> #REF!
C13: 材料费合计 | F13: =F9+F10 -> #REF! | G13: =G9+G10 -> #REF! | H13: =H9+H10 -> #REF! | I13: =I9+I10 -> #REF! | J13: =J9+J10 -> #REF! | K13: =K9+K10 -> #REF! | L13: =L9+L10 -> #REF! | M13: =M9+M10 -> #REF! | ... U13: =U9+U10 -> #REF!

Sheet 燃料动力
A2: 项目 | B2: 2016（7-12） | C2: 2017 | D2: 2018 | E2: 2019 | F2: 2020 | G2: 2021 | H2: 2022 | I2: 2023 | J2: 2024 | K2: 2025 | L2: 2026-2039 | M2: 2040 | N2: 2041-2043 | O2: 2044 | P2: 2045-2048 | Q2: 2049-2051
A3: 水 | B3: =ROUND(B4*B5/10000,2) -> 0.3 | C3: =ROUND(C4*C5/10000,2) -> 0.6 | D3: =ROUND(D4*D5/10000,2) -> 0.6 | E3: =ROUND(E4*E5/10000,2) -> 0.6 | F3: =ROUND(F4*F5/10000,2) -> 0.9 | G3: =ROUND(G4*G5/10000,2) -> 0.9 | H3: =ROUND(H4*H5/10000,2) -> 0.9 | I3: =ROUND(I4*I5/10000,2) -> 1.2 | ... Q3: =ROUND(Q4*Q5/10000,2) -> 0.3
A4: 单价 | B4: =$R$4 -> 1.17 | C4: =$R$4 -> 1.17 | D4: =$R$4 -> 1.17 | E4: =$R$4 -> 1.17 | F4: =$R$4 -> 1.17 | G4: =$R$4 -> 1.17 | H4: =$R$4 -> 1.17 | I4: =$R$4 -> 1.17 | ... Q4: =$R$4 -> 1.17 | R4: 1.17
A5: 数量 | B5: =14*365/2 -> 2555 | C5: =365*14 -> 5110 | D5: =365*14 -> 5110 | E5: =365*14 -> 5110 | F5: =365*21 -> 7665 | G5: =365*21 -> 7665 | H5: =365*21 -> 7665 | I5: =365*28 -> 10220 | J5: =365*28 -> 10220 | K5: =365*28 -> 10220 | L5: =365*28 -> 10220 | M5: =365*21 -> 7665 | N5: =365*21 -> 7665 | O5: =365*21 -> 7665 | P5: =365*14 -> 5110 | Q5: =365*7 -> 2555
A6: 电 | B6: =ROUND(B7*B8,2) -> #REF! | C6: =ROUND(C7*C8,2) -> #REF! | D6: =ROUND(D7*D8,2) -> #REF! | E6: =ROUND(E7*E8,2) -> #REF! | F6: =ROUND(F7*F8,2) -> #REF! | G6: =ROUND(G7*G8,2) -> #REF! | H6: =ROUND(H7*H8,2) -> #REF! | I6: =ROUND(I7*I8,2) -> #REF! | ... Q6: =ROUND(Q7*Q8,2) -> #REF!
A7: 单价 | B7: =$R$7 -> 0.53 | C7: =$R$7 -> 0.53 | D7: =$R$7 -> 0.53 | E7: =$R$7 -> 0.53 | F7: =$R$7 -> 0.53 | G7: =$R$7 -> 0.53 | H7: =$R$7 -> 0.53 | I7: =$R$7 -> 0.53 | ... Q7: =$R$7 -> 0.53 | R7: 0.53
A8: 数量（万kw.h) | B8: =ROUND('收入--历史经营情况分析'!#REF!*燃料动力!$R$8,2) -> #REF! | C8: =ROUND('收入--历史经营情况分析'!#REF!*燃料动力!$R$8,2) -> #REF! | D8: =ROUND('收入--历史经营情况分析'!#REF!*燃料动力!$R$8,2) -> #REF! | E8: =ROUND('收入--历史经营情况分析'!#REF!*燃料动力!$R$8,2) -> #REF! | F8: =ROUND('收入--历史经营情况分析'!#REF!*燃料动力!$R$8,2) -> #REF! | G8: =ROUND('收入--历史经营情况分析'!#REF!*燃料动力!$R$8,2) -> #REF! | H8: =ROUND('收入--历史经营情况分析'!#REF!*燃料动力!$R$8,2) -> #REF! | I8: =ROUND('收入--历史经营情况分析'!#REF!*燃料动力!$R$8,2) -> #REF! | ... Q8: =ROUND('收入--历史经营情况分析'!#REF!*燃料动力!$R$8,2) -> #REF! | R8: 0.24
A9: 外购燃料及动力费合计 | B9: =B3+B6 -> #REF! | C9: =C3+C6 -> #REF! | D9: =D3+D6 -> #REF! | E9: =E3+E6 -> #REF! | F9: =F3+F6 -> #REF! | G9: =G3+G6 -> #REF! | H9: =H3+H6 -> #REF! | I9: =I3+I6 -> #REF! | ... Q9: =Q3+Q6 -> #REF!
B12: 水： | C12: 处理一万吨水日用水量约7吨

Sheet 经营费用
B2: 2016（7-12） | C2: 2017 | D2: 2018 | E2: 2019 | F2: 2020 | G2: 2021 | H2: 2022 | I2: 2023 | J2: 2024 | K2: 2025 | L2: 2026-2039 | M2: 2040 | N2: 2041-2043 | O2: 2044 | P2: 2045-2048 | Q2: 2049-2051
A3: 工资及员工费用 | H3: =人员费用预测表!#REF! -> #REF! | I3: =人员费用预测表!#REF! -> #REF! | J3: =人员费用预测表!#REF! -> #REF! | K3: =人员费用预测表!#REF! -> #REF! | P3: =人员费用预测表!#REF! -> #REF! | Q3: =SUM(B3:P3) -> #REF!
A4: 办公费 | H4: =ROUND(H3*$S$4,2) -> #REF! | I4: =ROUND(I3*$S$4,2) -> #REF! | J4: =ROUND(J3*$S$4,2) -> #REF! | K4: =K3*0.5% -> #REF! | P4: =P3*0.5% -> #REF! | Q4: =SUM(B4:P4) -> #REF! | R4: 按照销售工资的5% | S4: 0.05
A5: 交际费 | B5: =ROUND('收入--历史经营情况分析'!#REF!*$S$5,2) -> #REF! | C5: =ROUND('收入--历史经营情况分析'!#REF!*$S$5,2) -> #REF! | D5: =ROUND('收入--历史经营情况分析'!#REF!*$S$5,2) -> #REF! | E5: =ROUND('收入--历史经营情况分析'!#REF!*$S$5,2) -> #REF! | F5: =ROUND('收入--历史经营情况分析'!#REF!*$S$5,2) -> #REF! | G5: =ROUND('收入--历史经营情况分析'!#REF!*$S$5,2) -> #REF! | H5: =ROUND('收入--历史经营情况分析'!#REF!*$S$5,2) -> #REF! | I5: =ROUND('收入--历史经营情况分析'!#REF!*$S$5,2) -> #REF! | ... Q5: =ROUND('收入--历史经营情况分析'!#REF!*$S$5,2) -> #REF! | R5: 按照收入的0.5%
A6: 车辆交通费 | B6: =ROUND('收入--历史经营情况分析'!#REF!*$S$6,2) -> #REF! | C6: =ROUND('收入--历史经营情况分析'!#REF!*$S$6,2) -> #REF! | D6: =ROUND('收入--历史经营情况分析'!#REF!*$S$6,2) -> #REF! | E6: =ROUND('收入--历史经营情况分析'!#REF!*$S$6,2) -> #REF! | F6: =ROUND('收入--历史经营情况分析'!#REF!*$S$6,2) -> #REF! | G6: =ROUND('收入--历史经营情况分析'!#REF!*$S$6,2) -> #REF! | H6: =ROUND('收入--历史经营情况分析'!#REF!*$S$6,2) -> #REF! | I6: =ROUND('收入--历史经营情况分析'!#REF!*$S$6,2) -> #REF! | ... Q6: =ROUND('收入--历史经营情况分析'!#REF!*$S$6,2) -> #REF! | R6: 按照收入的0.5%
A7: 广告费
A8: 差旅费 | B8: =ROUND('收入--历史经营情况分析'!#REF!*经营费用!$S$8,2) -> #REF! | C8: =ROUND('收入--历史经营情况分析'!#REF!*经营费用!$S$8,2) -> #REF! | D8: =ROUND('收入--历史经营情况分析'!#REF!*经营费用!$S$8,2) -> #REF! | E8: =ROUND('收入--历史经营情况分析'!#REF!*经营费用!$S$8,2) -> #REF! | F8: =ROUND('收入--历史经营情况分析'!#REF!*经营费用!$S$8,2) -> #REF! | G8: =ROUND('收入--历史经营情况分析'!#REF!*经营费用!$S$8,2) -> #REF! | H8: =ROUND('收入--历史经营情况分析'!#REF!*经营费用!$S$8,2) -> #REF! | I8: =ROUND('收入--历史经营情况分析'!#REF!*经营费用!$S$8,2) -> #REF! | ... Q8: =ROUND('收入--历史经营情况分析'!#REF!*经营费用!$S$8,2) -> #REF! | R8: 按照收入的0.2%
A9: 合计 | B9: =SUM(B3:B8) -> #REF! | C9: =SUM(C3:C8) -> #REF! | D9: =SUM(D3:D8) -> #REF! | E9: =SUM(E3:E8) -> #REF! | F9: =SUM(F3:F8) -> #REF! | G9: =SUM(G3:G8) -> #REF! | H9: =SUM(H3:H8) -> #REF! | I9: =SUM(I3:I8) -> #REF! | ... Q9: =SUM(Q3:Q8) -> #REF!

Sheet 人员费用预测表
A1: 莆田华科 2016年6月份工资表
A3: 编 号 | B3: 姓名 | C3: 标准工资 | D3: 缺勤 天数 | E3: 扣缺勤 | F3: 午餐补贴 | G3: 通讯补贴 | I3: 计税工资 | J3: 个税 | K3: 实发工资
B4: 姓名 | C4: 标准工资 | D4: 缺勤 天数 | E4: 扣缺勤 | F4: 午餐补贴 | G4: 通讯补贴 | I4: 计税工资 | J4: 个税 | K4: 实发工资
A5: 1 | I5: =#REF!-#REF! -> #REF! | J5: =ROUND(IF((I5-msjs1)>0,(I5-msjs1)*VLOOKUP((I5-msjs1),ysfw1,4)-VLOOKUP((I5-msjs1),ysfw1,5),0),2) -> #REF! | K5: =I5-J5 -> #REF!
A6: 2 | I6: =#REF!-#REF! -> #REF! | J6: =ROUND(IF((I6-msjs1)>0,(I6-msjs1)*VLOOKUP((I6-msjs1),ysfw1,4)-VLOOKUP((I6-msjs1),ysfw1,5),0),2) -> #REF! | K6: =I6-J6 -> #REF!
A7: 3 | I7: =#REF!-#REF! -> #REF! | J7: =ROUND(IF((I7-msjs1)>0,(I7-msjs1)*VLOOKUP((I7-msjs1),ysfw1,4)-VLOOKUP((I7-msjs1),ysfw1,5),0),2) -> #REF! | K7: =I7-J7 -> #REF!
A8: 4 | I8: =#REF!-#REF! -> #REF! | J8: =ROUND(IF((I8-msjs1)>0,(I8-msjs1)*VLOOKUP((I8-msjs1),ysfw1,4)-VLOOKUP((I8-msjs1),ysfw1,5),0),2) -> #REF! | K8: =I8-J8 -> #REF!
A9: 5 | I9: =#REF!-#REF! -> #REF! | J9: =ROUND(IF((I9-msjs1)>0,(I9-msjs1)*VLOOKUP((I9-msjs1),ysfw1,4)-VLOOKUP((I9-msjs1),ysfw1,5),0),2) -> #REF! | K9: =I9-J9 -> #REF!
A10: 6 | I10: =#REF!-#REF! -> #REF! | J10: =ROUND(IF((I10-msjs1)>0,(I10-msjs1)*VLOOKUP((I10-msjs1),ysfw1,4)-VLOOKUP((I10-msjs1),ysfw1,5),0),2) -> #REF! | K10: =I10-J10 -> #REF!
A11: 7 | I11: =#REF!-#REF! -> #REF! | J11: =ROUND(IF((I11-msjs1)>0,(I11-msjs1)*VLOOKUP((I11-msjs1),ysfw1,4)-VLOOKUP((I11-msjs1),ysfw1,5),0),2) -> #REF! | K11: =I11-J11 -> #REF!
A12: 8 | I12: =#REF!-#REF! -> #REF! | J12: =ROUND(IF((I12-msjs1)>0,(I12-msjs1)*VLOOKUP((I12-msjs1),ysfw1,4)-VLOOKUP((I12-msjs1),ysfw1,5),0),2) -> #REF! | K12: =I12-J12 -> #REF!
A13: 9 | I13: =#REF!-#REF! -> #REF! | J13: =ROUND(IF((I13-msjs1)>0,(I13-msjs1)*VLOOKUP((I13-msjs1),ysfw1,4)-VLOOKUP((I13-msjs1),ysfw1,5),0),2) -> #REF! | K13: =I13-J13 -> #REF!
A14: 10 | I14: =#REF!-#REF! -> #REF! | J14: =ROUND(IF((I14-msjs1)>0,(I14-msjs1)*VLOOKUP((I14-msjs1),ysfw1,4)-VLOOKUP((I14-msjs1),ysfw1,5),0),2) -> #REF! | K14: =I14-J14 -> #REF!
A15: 11 | I15: =#REF!-#REF! -> #REF! | J15: =ROUND(IF((I15-msjs1)>0,(I15-msjs1)*VLOOKUP((I15-msjs1),ysfw1,4)-VLOOKUP((I15-msjs1),ysfw1,5),0),2) -> #REF! | K15: =I15-J15 -> #REF!
A16: 12 | I16: =#REF!-#REF! -> #REF! | J16: =ROUND(IF((I16-msjs1)>0,(I16-msjs1)*VLOOKUP((I16-msjs1),ysfw1,4)-VLOOKUP((I16-msjs1),ysfw1,5),0),2) -> #REF! | K16: =I16-J16 -> #REF!
... A20: 16 | I20: =#REF!-#REF! -> #REF! | J20: =ROUND(IF((I20-msjs1)>0,(I20-msjs1)*VLOOKUP((I20-msjs1),ysfw1,4)-VLOOKUP((I20-msjs1),ysfw1,5),0),2) -> #REF! | K20: =I20-J20 -> #REF!
A21: 合计 | C21: =SUM(C5:C20) -> 0 | D21: =SUM(D5:D20) -> 0 | E21: =SUM(E5:E20) -> 0 | F21: =SUM(F5:F20) -> 0 | G21: =SUM(G5:G20) -> 0 | I21: =SUM(I5:I20) -> #REF! | J21: =SUM(J5:J20) -> #REF! | K21: =SUM(K5:K20) -> #REF!
A22: 莆田华科 2016年6月份工资表
A24: 编 号 | B24: 姓名 | C24: 标准工资 | D24: 缺勤 天数 | E24: 扣缺勤 | F24: 午餐 补贴 | G24: 通讯 补贴 | I24: 计税工资加项 | J24: 计税工资 | K24: 个税 | L24: 实发工资
B25: 姓名 | C25: 标准工资 | D25: 缺勤 天数 | E25: 扣缺勤 | F25: 午餐补贴 | G25: 通讯补贴 | I25: 计税工资加项 | J25: 计税工资 | K25: 个税
A26: 1 | I26: 0 | J26: =#REF!-#REF!-#REF!+I26 -> #REF! | K26: =ROUND(IF((J26-msjs1)>0,(J26-msjs1)*VLOOKUP((J26-msjs1),ysfw1,4)-VLOOKUP((J26-msjs1),ysfw1,5),0),2) -> #REF! | L26: =#REF!-#REF!-#REF!-K26 -> #REF!
A27: 2 | I27: =#REF!-#REF! -> #REF! | J27: =#REF!-#REF!-#REF!+I27 -> #REF! | K27: =ROUND(IF((J27-msjs1)>0,(J27-msjs1)*VLOOKUP((J27-msjs1),ysfw1,4)-VLOOKUP((J27-msjs1),ysfw1,5),0),2) -> #REF! | L27: =#REF!-#REF!-#REF!-K27 -> #REF!
A28: 3 | I28: 0 | J28: =#REF!-#REF!-#REF!+I28 -> #REF! | K28: =ROUND(IF((J28-msjs1)>0,(J28-msjs1)*VLOOKUP((J28-msjs1),ysfw1,4)-VLOOKUP((J28-msjs1),ysfw1,5),0),2) -> #REF! | L28: =#REF!-#REF!-#REF!-K28 -> #REF!
A29: 4 | I29: =#REF!-#REF! -> #REF! | J29: =#REF!-#REF!-#REF!+I29 -> #REF! | K29: =ROUND(IF((J29-msjs1)>0,(J29-msjs1)*VLOOKUP((J29-msjs1),ysfw1,4)-VLOOKUP((J29-msjs1),ysfw1,5),0),2) -> #REF! | L29: =#REF!-#REF!-#REF!-K29 -> #REF!
A30: 5 | I30: =#REF!-#REF! -> #REF! | J30: =#REF!-#REF!-#REF!+I30 -> #REF! | K30: =ROUND(IF((J30-msjs1)>0,(J30-msjs1)*VLOOKUP((J30-msjs1),ysfw1,4)-VLOOKUP((J30-msjs1),ysfw1,5),0),2) -> #REF! | L30: =#REF!-#REF!-#REF!-K30 -> #REF!
A31: 6 | I31: 0 | J31: =#REF!-#REF!-#REF!+I31 -> #REF! | K31: =ROUND(IF((J31-msjs1)>0,(J31-msjs1)*VLOOKUP((J31-msjs1),ysfw1,4)-VLOOKUP((J31-msjs1),ysfw1,5),0),2) -> #REF! | L31: =#REF!-#REF!-#REF!-K31 -> #REF!
A32: 7 | J32: =#REF!-#REF!-#REF!+I32 -> #REF! | K32: =ROUND(IF((J32-msjs1)>0,(J32-msjs1)*VLOOKUP((J32-msjs1),ysfw1,4)-VLOOKUP((J32-msjs1),ysfw1,5),0),2) -> #REF! | L32: =#REF!-#REF!-#REF!-K32 -> #REF!
A33: 8 | I33: 0 | J33: =#REF!-#REF!-#REF!+I33 -> #REF! | K33: =ROUND(IF((J33-msjs1)>0,(J33-msjs1)*VLOOKUP((J33-msjs1),ysfw1,4)-VLOOKUP((J33-msjs1),ysfw1,5),0),2) -> #REF! | L33: =#REF!-#REF!-#REF!-K33 -> #REF!
A34: 9 | I34: =#REF!-#REF! -> #REF! | J34: =#REF!-#REF!-#REF!+I34 -> #REF! | K34: =ROUND(IF((J34-msjs1)>0,(J34-msjs1)*VLOOKUP((J34-msjs1),ysfw1,4)-VLOOKUP((J34-msjs1),ysfw1,5),0),2) -> #REF! | L34: =#REF!-#REF!-#REF!-K34 -> #REF!
A35: 10 | J35: =#REF!-#REF!-#REF!+I35 -> #REF! | K35: =ROUND(IF((J35-msjs1)>0,(J35-msjs1)*VLOOKUP((J35-msjs1),ysfw1,4)-VLOOKUP((J35-msjs1),ysfw1,5),0),2) -> #REF! | L35: =#REF!-#REF!-#REF!-K35 -> #REF!
A36: 11 | I36: 0 | J36: =#REF!-#REF!-#REF!+I36 -> #REF! | K36: =ROUND(IF((J36-msjs1)>0,(J36-msjs1)*VLOOKUP((J36-msjs1),ysfw1,4)-VLOOKUP((J36-msjs1),ysfw1,5),0),2) -> #REF! | L36: =#REF!-#REF!-#REF!-K36 -> #REF!
A37: 12 | J37: =#REF!-#REF!-#REF!+I37 -> #REF! | K37: =ROUND(IF((J37-msjs1)>0,(J37-msjs1)*VLOOKUP((J37-msjs1),ysfw1,4)-VLOOKUP((J37-msjs1),ysfw1,5),0),2) -> #REF! | L37: =#REF!-#REF!-#REF!-K37 -> #REF!
A38: 13 | I38: =#REF!-#REF! -> #REF! | J38: =#REF!-#REF!-#REF!+I38 -> #REF! | K38: =ROUND(IF((J38-msjs1)>0,(J38-msjs1)*VLOOKUP((J38-msjs1),ysfw1,4)-VLOOKUP((J38-msjs1),ysfw1,5),0),2) -> #REF! | L38: =#REF!-#REF!-#REF!-K38 -> #REF!
A39: 14 | J39: =#REF!-#REF!-#REF!+I39 -> #REF! | L39: =#REF!-#REF!-#REF!-K39 -> #REF!
A40: 15 | J40: =#REF!-#REF!-#REF!+I40 -> #REF! | L40: =#REF!-#REF!-#REF!-K40 -> #REF!
A41: 16 | J41: =#REF!-#REF!-#REF!+I41 -> #REF! | L41: =#REF!-#REF!-#REF!-K41 -> #REF!
A42: 合计 | C42: =SUM(C26:C41) -> 0 | D42: =SUM(D26:D41) -> 0 | E42: =SUM(E26:E41) -> 0 | F42: =SUM(F26:F41) -> 0 | G42: =SUM(G26:G41) -> 0 | I42: =SUM(I26:I41) -> #REF! | J42: =SUM(J26:J41) -> #REF! | K42: =SUM(K26:K41) -> #REF! | L42: =SUM(L26:L41) -> #REF!
A45: 金额单位：元 | B45: 2017年 | C45: 2018年 | D45: 2019年 | E45: 2020年 | F45: 2021年 | G45: 2022年
A46: 职工人数
A47: 总部
...

Sheet 管理费用预测表
A1: 管理费用预测表
Q2: =[35]封面!A11 -> 评估基准日:2017年12月31日
T3: 人民币万元
P4: 0.04 | Q4: 0.04 | R4: 0.04 | S4: 0.04 | T4: 0.04
C5: 历史费用情况 | O5: 三年平均 | P5: 未来费用预测
A6: 项目 | C6: =[35]未来收入预测表!C6 -> 2013年 | D6: =[35]未来收入预测表!D6 -> 2014年 | E6: 2013年 | G6: 2014年 | I6: =[35]未来收入预测表!E6 -> 2015年 | K6: =[35]未来收入预测表!F6 -> 2016年 | M6: =[35]未来收入预测表!G6 -> 2017年 | P6: =[35]未来收入预测表!H6 -> 2018年 | Q6: =[35]未来收入预测表!I6 -> 2019年 | R6: =[35]未来收入预测表!J6 -> 2020年 | S6: =[35]未来收入预测表!K6 -> 2021年 | T6: =[35]未来收入预测表!L6 -> 2022年
A7: 管理费用 | B7: 工资 | C7: 14748905 | D7: 10224824 | E7: 1474.89 | F7: =E7/'收入--历史经营情况分析'!#REF! -> #REF! | G7: 1022.48 | H7: =G7/'收入--历史经营情况分析'!#REF! -> #REF! | I7: 920.73 | J7: =I7/'收入--历史经营情况分析'!#REF! -> #REF! | K7: 771.42 | L7: =K7/'收入--历史经营情况分析'!#REF! -> #REF! | M7: 857.05 | N7: =M7/'收入--历史经营情况分析'!#REF! -> #REF! | O7: =(J7+L7+N7)/3 -> #REF! | V7: =U7*1.02 -> 0 | W7: =V7*1.02 -> 0 | X7: =W7*1.02 -> 0 | Y7: =X7*1.02 -> 0
B8: 社会保险费 | E8: 607.53 | F8: =E8/'收入--历史经营情况分析'!#REF! -> #REF! | G8: 520.07 | H8: =G8/'收入--历史经营情况分析'!#REF! -> #REF! | I8: 551.4 | J8: =I8/'收入--历史经营情况分析'!#REF! -> #REF! | K8: 550.74 | L8: =K8/'收入--历史经营情况分析'!#REF! -> #REF! | M8: 690.42 | N8: =M8/'收入--历史经营情况分析'!#REF! -> #REF! | O8: =(J8+L8+N8)/3 -> #REF! | V8: =N8*1.02 -> #REF! | W8: =O8*1.02 -> #REF! | X8: =P8*1.02 -> 0 | Y8: =Y9-Y7 -> 0
B9: 租赁费 | E9: 113.94 | F9: =E9/'收入--历史经营情况分析'!#REF! -> #REF! | G9: 89.82 | H9: =G9/'收入--历史经营情况分析'!#REF! -> #REF! | I9: 96.38 | J9: =I9/'收入--历史经营情况分析'!#REF! -> #REF! | K9: 98.69 | L9: =K9/'收入--历史经营情况分析'!#REF! -> #REF! | M9: 52.67 | N9: =M9/'收入--历史经营情况分析'!#REF! -> #REF! | O9: =(J9+L9+N9)/3 -> #REF! | U9: =P7+P8 -> 0 | V9: =Q7+Q8 -> 0 | W9: =R7+R8 -> 0 | X9: =S7+S8 -> 0 | Y9: =T7+T8 -> 0
B10: 折旧费 | E10: 389.33 | F10: =E10/'收入--历史经营情况分析'!#REF! -> #REF! | G10: 355.71 | H10: =G10/'收入--历史经营情况分析'!#REF! -> #REF! | I10: 352.33 | J10: =I10/'收入--历史经营情况分析'!#REF! -> #REF! | K10: 249.66 | L10: =K10/'收入--历史经营情况分析'!#REF! -> #REF! | M10: 215.42 | N10: =M10/'收入--历史经营情况分析'!#REF! -> #REF! | O10: =(J10+L10+N10)/3 -> #REF!
B11: 办公费 | E11: 120.19 | F11: =E11/'收入--历史经营情况分析'!#REF! -> #REF! | G11: 137.97 | H11: =G11/'收入--历史经营情况分析'!#REF! -> #REF! | I11: 159.74 | J11: =I11/'收入--历史经营情况分析'!#REF! -> #REF! | K11: 89.01 | L11: =K11/'收入--历史经营情况分析'!#REF! -> #REF! | M11: 40.28 | N11: =M11/'收入--历史经营情况分析'!#REF! -> #REF! | O11: =(L11+N11)/2 -> #REF!
B12: 税费 | C12: 1201928.8 | D12: 1379692.7 | E12: 139.11 | F12: =E12/'收入--历史经营情况分析'!#REF! -> #REF! | G12: 169.72 | H12: =G12/'收入--历史经营情况分析'!#REF! -> #REF! | I12: 105.68 | J12: =I12/'收入--历史经营情况分析'!#REF! -> #REF! | K12: 71.24 | L12: =K12/'收入--历史经营情况分析'!#REF! -> #REF! | M12: 16.17 | N12: =M12/'收入--历史经营情况分析'!#REF! -> #REF! | O12: =(J12+L12+N12)/3 -> #REF!
B13: 其他 | C13: 1391077 | D13: 1697191.3 | E13: 956.19 | F13: =E13/'收入--历史经营情况分析'!#REF! -> #REF! | G13: 743.39 | H13: =G13/'收入--历史经营情况分析'!#REF! -> #REF! | I13: 430.74 | J13: =I13/'收入--历史经营情况分析'!#REF! -> #REF! | K13: 489.94 | L13: =K13/'收入--历史经营情况分析'!#REF! -> #REF! | M13: 374.94 | N13: =M13/'收入--历史经营情况分析'!#REF! -> #REF! | O13: =(J13+L13+N13)/3 -> #REF!
B14: 合计 | C14: =SUM(C7:C13) -> 17341911 | D14: =SUM(D7:D13) -> 13301708 | E14: =SUM(E7:E13) -> 3801.18 | F14: =SUM(F7:F13) -> #REF! | G14: =SUM(G7:G13) -> 3039.16 | H14: =SUM(H7:H13) -> #REF! | I14: =SUM(I7:I13) -> 2617 | J14: =SUM(J7:J13) -> #REF! | ... L14: =SUM(L7:L13) -> #REF! | M14: =2289.78 -> 2289.78 | N14: =M14/'收入--历史经营情况分析'!#REF! -> #REF! | O14: =(J14+L14+N14)/3 -> #REF!
A16: =[35]封面!A17 -> 被评估单位填表人：
A18: =[35]封面!A15 -> 填表日期：

Sheet 销售费用预测表
A1: 销售费用预测表
O2: =[35]封面!A11 -> 评估基准日:2017年12月31日
P3: 人民币元
C5: 历史费用情况 | M5: 3年平均 | N5: 未来费用预测
A6: 项目 | C6: =[35]未来收入预测表!C6 -> 2013年 | E6: =[35]未来收入预测表!D6 -> 2014年 | G6: =[35]未来收入预测表!E6 -> 2015年 | I6: =[35]未来收入预测表!F6 -> 2016年 | K6: =[35]未来收入预测表!G6 -> 2017年 | N6: =[35]未来收入预测表!H6 -> 2018年 | O6: =[35]未来收入预测表!I6 -> 2019年 | P6: =[35]未来收入预测表!J6 -> 2020年 | Q6: =[35]未来收入预测表!K6 -> 2021年 | R6: =[35]未来收入预测表!L6 -> 2022年
A7: 销售费用 | B7: 工资 | C7: 4197.51 | D7: =C7/'收入--历史经营情况分析'!#REF! -> #REF! | E7: 5296.8829 | F7: =E7/'收入--历史经营情况分析'!#REF! -> #REF! | G7: 4161.72 | H7: =G7/'收入--历史经营情况分析'!#REF! -> #REF! | I7: 4241.4 | J7: =I7/'收入--历史经营情况分析'!#REF! -> #REF! | K7: 5179.95 | L7: =K7/'收入--历史经营情况分析'!#REF! -> #REF!
B8: 租赁费 | C8: 12497.84 | D8: =C8/'收入--历史经营情况分析'!#REF! -> #REF! | E8: 5173.3567 | F8: =E8/'收入--历史经营情况分析'!#REF! -> #REF! | G8: 5369.8 | H8: =G8/'收入--历史经营情况分析'!#REF! -> #REF! | I8: 6859.83 | J8: =I8/'收入--历史经营情况分析'!#REF! -> #REF! | K8: 8323.9 | L8: =K8/'收入--历史经营情况分析'!#REF! -> #REF! | S8: =(O8-N8)/N8 -> #DIV/0! | T8: =(P8-O8)/O8 -> #DIV/0! | U8: =(Q8-P8)/P8 -> #DIV/0! | V8: =(R8-Q8)/Q8 -> #DIV/0!
B9: 物业管理费 | C9: 2638.4 | D9: =C9/'收入--历史经营情况分析'!#REF! -> #REF! | E9: 709.17654 | F9: =E9/'收入--历史经营情况分析'!#REF! -> #REF! | G9: 956.2 | H9: =G9/'收入--历史经营情况分析'!#REF! -> #REF! | I9: 1835.7 | J9: =I9/'收入--历史经营情况分析'!#REF! -> #REF! | K9: 1936.47 | L9: =K9/'收入--历史经营情况分析'!#REF! -> #REF! | M9: =(H9+J9+L9)/3 -> #REF!
B10: 折旧与摊销 | C10: 558.79 | D10: =C10/'收入--历史经营情况分析'!#REF! -> #REF! | E10: 422.03609 | F10: =E10/'收入--历史经营情况分析'!#REF! -> #REF! | G10: 375.65 | H10: =G10/'收入--历史经营情况分析'!#REF! -> #REF! | I10: 343.4 | J10: =I10/'收入--历史经营情况分析'!#REF! -> #REF! | K10: 376.69 | L10: =K10/'收入--历史经营情况分析'!#REF! -> #REF! | M10: =(H10+J10+L10)/3 -> #REF!
B11: 水电费 | C11: 1063.62 | D11: =C11/'收入--历史经营情况分析'!#REF! -> #REF! | E11: 558.25053 | F11: =E11/'收入--历史经营情况分析'!#REF! -> #REF! | G11: 524.83 | H11: =G11/'收入--历史经营情况分析'!#REF! -> #REF! | I11: 496.44 | J11: =I11/'收入--历史经营情况分析'!#REF! -> #REF! | K11: 623.29 | L11: =K11/'收入--历史经营情况分析'!#REF! -> #REF! | M11: =(H11+J11+L11)/3 -> #REF!
B12: 商场费用 | C12: 1153.72 | D12: =C12/'收入--历史经营情况分析'!#REF! -> #REF! | E12: 1066.4156 | F12: =E12/'收入--历史经营情况分析'!#REF! -> #REF! | G12: 1202.34 | H12: =G12/'收入--历史经营情况分析'!#REF! -> #REF! | I12: 996.9 | J12: =I12/'收入--历史经营情况分析'!#REF! -> #REF! | K12: 1114.68 | L12: =K12/'收入--历史经营情况分析'!#REF! -> #REF! | M12: 0.011 | S12: =(N12-K12)/K12 -> -1 | T12: =(O12-N12)/N12 -> #DIV/0! | U12: =(P12-O12)/O12 -> #DIV/0! | V12: =(Q12-P12)/P12 -> #DIV/0! | W12: =(R12-Q12)/Q12 -> #DIV/0!
B13: 运杂费 | C13: 283.65 | D13: =C13/'收入--历史经营情况分析'!#REF! -> #REF! | E13: 215.0101 | F13: =E13/'收入--历史经营情况分析'!#REF! -> #REF! | G13: 283.67 | H13: =G13/'收入--历史经营情况分析'!#REF! -> #REF! | I13: 268.33 | J13: =I13/'收入--历史经营情况分析'!#REF! -> #REF! | K13: 254.41 | L13: =K13/'收入--历史经营情况分析'!#REF! -> #REF! | M13: =(H13+J13+L13)/3 -> #REF! | S13: =(N13-K13)/K13 -> -1 | T13: =(O13-N13)/N13 -> #DIV/0! | U13: =(P13-O13)/O13 -> #DIV/0! | V13: =(Q13-P13)/P13 -> #DIV/0! | W13: =(R13-Q13)/Q13 -> #DIV/0!
B14: 包装费 | C14: 124.73 | D14: =C14/'收入--历史经营情况分析'!#REF! -> #REF! | E14: 105.86382 | F14: =E14/'收入--历史经营情况分析'!#REF! -> #REF! | G14: 107.64 | H14: =G14/'收入--历史经营情况分析'!#REF! -> #REF! | I14: 104.48 | J14: =I14/'收入--历史经营情况分析'!#REF! -> #REF! | K14: 110.91 | L14: =K14/'收入--历史经营情况分析'!#REF! -> #REF! | M14: =(H14+J14+L14)/3 -> #REF! | S14: =(N14-K14)/K14 -> -1 | T14: =(O14-N14)/N14 -> #DIV/0! | U14: =(P14-O14)/O14 -> #DIV/0! | V14: =(Q14-P14)/P14 -> #DIV/0! | W14: =(R14-Q14)/Q14 -> #DIV/0!
B15: 修理费 | C15: 165.18 | D15: =C15/'收入--历史经营情况分析'!#REF! -> #REF! | E15: 138.79471 | F15: =E15/'收入--历史经营情况分析'!#REF! -> #REF! | G15: 121.99 | H15: =G15/'收入--历史经营情况分析'!#REF! -> #REF! | I15: 169.2 | J15: =I15/'收入--历史经营情况分析'!#REF! -> #REF! | K15: 167.68 | L15: =K15/'收入--历史经营情况分析'!#REF! -> #REF! | M15: =(H15+J15+L15)/3 -> #REF! | S15: =(N15-K15)/K15 -> -1 | T15: =(O15-N15)/N15 -> #DIV/0! | U15: =(P15-O15)/O15 -> #DIV/0! | V15: =(Q15-P15)/P15 -> #DIV/0! | W15: =(R15-Q15)/Q15 -> #DIV/0!
B16: 差旅费 | C16: 156.39 | D16: =C16/'收入--历史经营情况分析'!#REF! -> #REF! | E16: 109.70452 | F16: =E16/'收入--历史经营情况分析'!#REF! -> #REF! | G16: 126.49 | H16: =G16/'收入--历史经营情况分析'!#REF! -> #REF! | I16: 161.55 | J16: =I16/'收入--历史经营情况分析'!#REF! -> #REF! | K16: 118.79 | L16: =K16/'收入--历史经营情况分析'!#REF! -> #REF! | M16: =(H16+J16+L16)/3 -> #REF! | S16: =(N16-K16)/K16 -> -1 | T16: =(O16-N16)/N16 -> #DIV/0! | U16: =(P16-O16)/O16 -> #DIV/0! | V16: =(Q16-P16)/P16 -> #DIV/0! | W16: =(R16-Q16)/Q16 -> #DIV/0!
B17: 其他 | C17: 1937.8536 | D17: =C17/'收入--历史经营情况分析'!#REF! -> #REF! | E17: 558.73832 | F17: =E17/'收入--历史经营情况分析'!#REF! -> #REF! | G17: =536.48+207.86 -> 744.34 | H17: =G17/'收入--历史经营情况分析'!#REF! -> #REF! | I17: =440.29+56.1 -> 496.39 | J17: =I17/'收入--历史经营情况分析'!#REF! -> #REF! | K17: =346.85+2.73 -> 349.58 | L17: =K17/'收入--历史经营情况分析'!#REF! -> #REF! | M17: =(H17+J17+L17)/3 -> #REF! | S17: =(N17-K17)/K17 -> -1 | T17: =(O17-N17)/N17 -> #DIV/0! | U17: =(P17-O17)/O17 -> #DIV/0! | V17: =(Q17-P17)/P17 -> #DIV/0! | W17: =(R17-Q17)/Q17 -> #DIV/0!
B18: 合计 | C18: =SUM(C7:C17) -> 24777.684 | E18: =SUM(E7:E17) -> 14354.23 | G18: 13766.8 | H18: =G18/'收入--历史经营情况分析'!#REF! -> #REF! | I18: 15917.53 | J18: =I18/'收入--历史经营情况分析'!#REF! -> #REF! | K18: 18561.55 | L18: =K18/'收入--历史经营情况分析'!#REF! -> #REF! | M18: =(H18+J18+L18)/3 -> #REF! | N18: =SUM(N7:N16) -> 0 | O18: =SUM(O7:O16) -> 0 | P18: =SUM(P7:P16) -> 0 | Q18: =SUM(Q7:Q16) -> 0 | R18: =SUM(R7:R16) -> 0

Sheet 租赁费预测
A1: 店铺序号 | B1: 公司 | C1: 单位 | D1: 地区 | E1: 店铺性质 | F1: 店铺业态 | G1: 店铺名称 | H1: 金蝶系统名称 | I1: 承租方 | J1: 出租方 | K1: 地址 | L1: 面积（m2) | M1: 合同期限/年租金 | N1: 租金单价㎡/日 | O1: 2018年租金测算 | P1: 2019年 | Q1: 2020年 | R1: 2021年 | S1: 2022年 | T1: 租金上涨率 | U1: 物业管理费 | V1: 物业费测算 | W1: 关店时间
A2: 1 | B2: 湖北杰之行 | C2: 零售 | D2: 武汉 | E2: 直营 | F2: 地铺店 | G2: 江北红房子耐克、匡威 | H2: 江北红房子 | I2: 湖北杰之行 | J2: 武汉市凡荣服饰有限公司 | K2: 武汉市江岸区江汉路14号 | L2: 180 | M2: 2013.08.01-2019.07.31（2300000元/年） | N2: =O2/180/365 -> 35.00761 | O2: 2300000 | T2: 不涨
A3: 2 | B3: 湖北杰之行 | C3: 零售 | D3: 武汉 | E3: 直营 | F3: 运动城 | G3: 江南光谷集合店 | H3: 江南光谷集合店 | I3: 湖北杰之行 | J3: 湖北胜道体育用品有限公司 | K3: 武汉东湖开发区光谷街3号世界城光谷步行街 | L3: 1784.57 | M3: 2015.01.01-2024.12.31(租金:100万元/年) | N3: =O3/L3/365 -> 1.5352304 | O3: 1000000 | T3: 不涨
B4: 湖北杰之行 | C4: 零售 | D4: 武汉 | E4: 直营 | F4: 运动城 | G4: 江南光谷集合店 | H4: 江南光谷集合店 | I4: 湖北杰之行 | J4: 湖北胜道体育用品有限公司 | K4: 武汉东湖开发区光谷街3号世界城光谷步行街 | L4: 2466.43 | M4: 2017.09.10-2021.01.09（固定租金900万/年；抽成租金保底营业额833.33万*5%*12/年)（2017.09.10-2018.01.09免租） | N4: =O4/L4/365 -> 15.551288 | O4: =(9000000+8333333*0.05*12) -> 14000000 | T4: 不涨 | U4: 2017.09.10-2021.01.09（物业管理费100万/年）（2017.09.10-2018.01.09免租） | V4: 10000000
A5: 3 | B5: 湖北杰之行 | C5: 零售 | D5: 武汉 | E5: 直营 | F5: 地铺店 | G5: 江南光谷世界城万斯 | H5: 江南光谷世界城万斯 | I5: 湖北杰之行 | J5: 武汉市世界城广场商业管理有限公司 | K5: 武汉市东湖新技术开发区珞瑜路世界城广场3035# | L5: 71.22 | M5: 2013.09.28-2015.09.27（租金：213660元/年） 2015.09.28-2016.09.27（租金：230748元/年） 2016.09.28-2017.09.27（租金：230748元/年） 2017.09.28-2018.09.27（租金：230748元/年） | N5: =O5/L5/365 -> 8.8765277 | O5: 230748 | T5: =(230748-213660)/213660/3 -> 0.026659178 | U5: 2013.09.28-2015.09.27（物业管理费：42732元/年） 2015.09.28-2016.09.27（物业管理费：42732元/年） 2016.09.28-2017.09.27（物业管理费：51278元/年） 2017.09.28-2018.09.27（物业管理费：51278元/年） | V5: 51278
A6: 4 | B6: 湖北杰之行 | C6: 零售 | D6: 武汉 | E6: 直营 | F6: 集合店 | G6: 武汉宜家集合店 | H6: 江北宜家集合店 | I6: 湖北杰之行 | J6: 武汉英特宜家置业有限公司 | K6: 武汉市桥口区长宜路1号购物中心L12层4-12-23-SU和4-12-24-SU号的物业 | L6: 425 | M6: 2015.01.12-2016.01.11(提成租金:为13%,基本租金:无;两者取其高) 2016.01.12-2017.01.11(基本租金:121.67元/平米/月,提成租金:14%,两者取其高) 2017.01.12-2018.01.11(基本租金:182.5元/平米/月,提成租金:15%,两者取其高) 免租期:首二个月的免租期,不付租金,但需付物业管理费\推广费\公共事业费等 | N6: 182.5 | O6: =L6*N6*12 -> 930750 | T6: =(182.5-121.67)/121.67 -> 0.49995891 | U6: 2015.01.12-2016.01.11物业费:70元/平米/月,推广费;12元/平米/月 2016.01.12-2017.01.11物业费:70元/平米/月,推广费:12.6元/平米/月 2017.01.12-2018.01.11物业费:70元/平米/月,推广费:13.23元/平米/月 | V6: =(70+13.23)*12*L6 -> 424473
A7: 5 | B7: 湖北杰之行 | C7: 零售 | D7: 武汉 | E7: 直营 | F7: 地铺店 | G7: 武汉宜家安德玛 | H7: 江北宜家安德玛 | I7: 湖北杰之行 | J7: 武汉英特宜家置业有限公司 | K7: 武汉市桥口区长宜路1号购物中心L11层4-11-26-SU单元号 | L7: 197 | M7: 2015.03.23-2016.03.22(基本租金:无 提成租金:比例为12%,) 2016.03.23-2017.03.22(基本租金:106.46元/平米/月,提成租金:13%,) 2017.03.23-2018.03.22(基本租金:182.5元/平米/月,提成比例:14%,) 免租期:指开业日起的首三个月 | U7: 2015.03.23-2016.03.22(物业费:70元/平米/月,推广费;12元/平米/月) 2016.03.23-2017.03.22(物业费:70元/平米/月,推广费:12.6元/平米/月) 2017.03.23-2018.03.22(物业费:70元/平米/月,推广费:13.23元/平米/月) | W7: 2017.06.15
A8: 6 | B8: 湖北杰之行 | C8: 零售 | D8: 武汉 | E8: 直营 | F8: 集合店 | G8: 中百唐家墩集合店 | H8: 武汉唐家墩集合店 | I8: 湖北杰之行 | J8: 中百仓储超市有限公司 | K8: 湖北省武汉市中百仓储购物广场唐家墩店二层 | L8: 270 | M8: 2015.05.01-2016.12.31(租金:31700元/月, 2017.01.01-2017.12.31(租金:34236元/月) 2018.01.01-2018.12.31(租金:36975元/月) 2019.01.01-2019.12.31(租金:39933元/月) | W8: 42826
A9: 7 | B9: 湖北杰之行 | C9: 零售 | D9: 武汉 | E9: 直营 | F9: 地铺店 | G9: 江南光谷世界城阿迪SH | H9: 江南光谷世界城阿迪SH | I9: 湖北杰之行 | J9: 武汉市世界城广场商业管理有限公司 | K9: 武汉市东湖新技术开发区珞瑜路世界城广场(149号) | L9: 150 | M9: 2014.12.20-2015.12.19(租金:684000元/年) 2015.12.20-2016.12.19(租金:752400元/年) 2016.12.20-2017.12.19(租金:828000元/年) | U9: 物业管理费:按3个月为一期结算,50元/月/平方米 营销推广费用:10元/月/平方米, | W9: 合同到期
B10: 湖北杰之行 | C10: 零售 | D10: 武汉 | E10: 直营 | F10: 地铺店 | G10: 江南光谷世界城阿迪SH | H10: 江南光谷世界城阿迪SH | I10: 湖北杰之行 | J10: 武汉市世界城广场商业管理有限公司 | K10: 武汉市东湖新技术开发区珞瑜路世界城广场(149号) | L10: 150 | M10: 2017.12.20-2018.03.31（租金：69000元/月） | N10: =O10/L10/365 -> 15.123288 | O10: =69000*12 -> 828000 | T10: =(828000-752400)/752400 -> 0.10047847 | U10: 物业管理费:,50元/月/平方米营销推广费用:10元/月/平方米,，按3个月为一期结算 | V10: =60*L10*12 -> 108000
A11: 8 | B11: 湖北杰之行 | C11: 零售 | D11: 武汉 | E11: 直营 | F11: 运动城 | G11: 江北菱角湖万达集合店 | H11: 江北菱角湖万达集合店 | I11: 湖北杰之行 | J11: 武汉万达广场投资有限公司 | K11: 武汉市江汉区新华下路63号菱角湖万达购物中心 | L11: 1605.88 | M11: 2015.08.01-2015.09.17（租金：232370.84元/月） 2015.09.17-2016.09.16（租金：2927968.89元/年） | U11: 2015.08.01-2015.09.17（物业：297922.8元/年） 2015.08.01-2015.09.17（物业：301006.15元/年） | W11: 合同到期
B12: 湖北杰之行 | C12: 零售 | D12: 武汉 | E12: 直营 | F12: 运动城 | G12: 江北菱角湖万达集合店 | H12: 江北菱角湖万达集合店 | I12: 湖北杰之行 | J12: 武汉万达广场投资有限公司 | K12: 武汉市江汉区新华下路63号菱角湖万达购物中心 | L12: 1605.88 | M12: 2016.12.18-2017.12.17(租金：3468700.80元/年） 2017.12.18-2018.12.17(租金：3468700.80元/年） 2018.12.18-2019.12.17(租金：3607448.88元/年） 2019.12.18-2020.12.17(租金：3751785.36元/年） 2020.12.18-2021.12.17(租金：3901902.96元/年） 2021.12.18-2022.12.17(租金：4057994.52元/年） | N12: =O12/L12/365 -> 5.9178082 | O12: 3468700.8 | T12: =(3607448.88-3468700.8)/3468700.8 -> 0.040000014 | U12: 2016.12.18-2017.12.17(物业：16元/平米） 2017.12.18-2018.12.17(物业：16元/平米） 2018.12.18-2019.12.17(物业：16.24元/平米） 2019.12.18-2020.12.17(物业：16.49元/平米） 2020.12.18-2021.12.17(物业：16.75元/平米） 2021.12.18-2022.12.17(物业：17.02元/平米） | V12: =16*L12*12 -> 308328.96
A13: 9 | B13: 湖北杰之行 | C13: 零售 | D13: 武汉 | E13: 直营 | F13: 运动城 | G13: 江北经开万达运动城 | H13: 江北经开万达集合店 | I13: 湖北杰之行 | J13: 武汉经开万达广场投资有限公司 | K13: 武汉市经开万达广场综合楼1F-A铺位, | L13: 2848.15 | M13: 2011.8.26-2012.8.25(租金:110元/月/平米) 2012.8.26-2013.8.25(租金:110元/月/平米) 2013.8.26-2014.8.25(租金:113.3元/月/平米) 2014.8.26-2015.8.25(租金:116.7元/月/平米) 2015.8.26-2016.8.25(租金:120.2元/月/平米) 2016.8.26-2017.8.25(租金:123.81元/月/平米) | U13: 2011.8.26-2012.8.25(物业费:6元/月/平米) 2012.8.26-2013.8.25(物业费:6元/月/平米) 2013.8.26-2014.8.25(物业费:6.24元/月/平米) 2014.8.26-2015.8.25(物业费:6.49元/月/平米) 2015.8.26-2016.8.25(物业费:6.75元/月/平米) 2016.8.26-2017.8.25(物业费:7.02元/月/平米) 2011.8.26-2017.8.25(空调费:10元/月/平米) | W13: 合同到期
B14: 湖北杰之行 | C14: 零售 | D14: 武汉 | E14: 直营 | F14: 运动城 | G14: 江北经开万达运动城 | H14: 江北经开万达集合店 | I14: 湖北杰之行 | J14: 武汉经开万达广场投资有限公司 | K14: 武汉市经开万达广场综合楼1F-A铺位, | L14: 2601 | M14: 2017.8.26-2019.8.25(租金:123.81元/月/平米) 2019.8.26-2020.8.25(租金:127.52元/月/平米) 2020.8.26-2021.8.25(租金:131.35元/月/平米) 2021.8.26-2022.8.25(租金:135.29元/月/平米) 2022.8.26-2023.8.25(租金:139.35元/月/平米) | N14: =O14/L14/365 -> 4.0704658 | O14: =123.81*L14*12 -> 3864357.7 | T14: =(127.52-123.81)/123.81 -> 0.029965269 | U14: 2017.8.26-2019.8.25(物业:17.02元/月/平米) 2019.8.26-2020.8.25(物业:17.30元/月/平米) 2020.8.26-2021.8.25(物业:17.59元/月/平米) 2021.8.26-2022.8.25(物业:17.89元/月/平米) 2022.8.26-2023.8.25(物业:18.21元/月/平米) | V14: =17.02*L14*12 -> 531228.24
A15: 10 | B15: 湖北杰之行 | D15: 武汉 | E15: 直营 | F15: 运动城 | G15: 江北经开跑步店 | H15: 江北经开万达集合店 | I15: 湖北杰之行 | J15: 湖北万达广场商业管理有限公司经济开发区分公司 | K15: 经开万达0008点位一 | L15: 30 | O15: 租金？ | U15: 2017.8.15-2018.8.15（物业：8800元/月）
A16: 11 | B16: 湖北杰之行 | C16: 零售 | D16: 武汉 | E16: 直营 | F16: 地铺店 | G16: 江南体院集合店 | H16: 江南体院集合店 | I16: 湖北杰之行 | J16: 湖北胜道体育用品有限公司 | K16: 武汉市洪山区珞南街珞瑜路476号 | L16: 1057 | M16: 2015.05.01-2018.04.30(租金:30万元/年) | N16: =O16/L16/365 -> 0.7775949 | O16: 300000 | T16: 不涨
A17: 12 | B17: 湖北杰之行 | C17: 零售 | D17: 武汉 | E17: 直营 | F17: 运动城 | G17: 江南麦当劳运动城 | H17: 江南麦当劳运动城 | I17: 湖北杰之行 | J17: 湖北胜道体育用品有限公司 | K17: 武汉市武昌区解放路338号(原340号)2栋杰之行运动城 | L17: 1126.65 | M17: 2015.08.01-2020.12.31(租金:100万元/年) | N17: =O17/L17/365 -> 2.4317455 | O17: 1000000 | T17: 不涨
A18: 13 | B18: 武汉杰锐 | C18: 零售 | D18: 武汉 | E18: 直营 | F18: 运动城 | G18: 江南光谷天地运动城 | H18: 江南光谷天地集合店 | I18: 武汉杰锐 | J18: 湖北长城建设实业有限公司 | K18: 武汉市东湖高新技术开发区关山大道591号光谷天地 | L18: 1800 | M18: 2011.07.01-2012.06.30（1944000元/年） 2012.07.01-2013.06.30（2052000元/年） 2013.07.01-2014.06.30（2160000元/年） 2014.07.01-2015.06.30（2268000元/年） 2015.07.01-2016.06.30（2376000元/年） | W18: 2016.07.05
A19: 14 | B19: 湖北杰之行 | C19: 零售 | D19: 武汉 | E19: 直营 | F19: 地铺店 | G19: 武汉凯德广场1818集合店 | H19: 江南凯德广场1818集合店 | I19: 湖北杰之行 | J19: 武汉凯辉中北商用置业有限公司 | K19: 凯德广场.1818,武汉"04层16*19号" | L19: 410.04 | M19: 2015.09.17-2017.09.16(月保底租金32803.2元/月) (提成租金月营业额的10%) 2017.09.17-2018.09.16(月保底租金36903.6元/月) (提成租金月营业额的11%) 2018.09.17-2019.09.16(月保底租金41004元/月) (提成租金月营业额的12%) 2019.09.17-2020.09.16(月保底租金45104.4元/月) (提成租金月营业额的13%) | N19: =O19/L19/365 -> 2.9589041 | O19: =36903.6*12 -> 442843.2 | T19: =(41004-36903.6)/36903.6 -> 0.11111111 | U19: 2015.09.17-2017.09.16(物业管理费24602.4元/月) 2017.09.17-2018.09.16 (物业管理费24602.4元/月) 2018.09.17-2019.09.16 (物业管理费24602.4元/月) 2019.09.17-2020.09.16 (物业管理费24602.4元/月) | V19: =24602.4*12 -> 295228.8 | W19: 原合同终止
B20: 湖北杰之行 | C20: 零售 | D20: 武汉 | E20: 直营 | F20: 地铺店 | G20: 武汉凯德广场1818集合店 | H20: 江南凯德广场1818集合店 | I20: 湖北杰之行 | J20: 武汉凯辉中北商用置业有限公司 | K20: 凯德广场.1818,武汉"04层16*19号" | L20: 260.87 | M20: 2016.12.10-2017.09.16（月保底租金19930.47元） 2017.09.17-2018.09.16（月保底租金22539.17元） 2018.09.17-2019.09.16（月保底租金25147.87元） 2019.09.17-2020.09.16（月保底租金27756.57元） | N20: =O20/L20/365 -> 61.751151 | O20: =22539.17*L20 -> 5879793.3 | T20: =(25147.87-22539.17)/22539.17 -> 0.11574073 | U20: 2016.12.10-2020.09.16（物业管理费16591.33元/月） | V20: 16591.33
A21: 15 | B21: 湖北杰之行 | C21: 零售 | D21: 武汉 | E21: 直营 | F21: 地铺店 | G21: 武汉摩尔城集合店 | H21: 江北王家湾摩尔城集合店 | I21: 湖北杰之行 | J21: 湖北恒信德龙实业有限公司武汉摩尔在管理分公司 | K21: 武汉市汉阳区龙阳大道特6号武汉摩尔城二层22-008号商铺(A区) | L21: 1080 | M21: 2015.10.01-2017.09.30(租金:61200元/月) 2017.10.01-2019.09.30(租金:72720元/月) 2019.10.01-2020.09.30(租金:85680元/月)或月营业额的15% | U21: 物业管理费:54000元/月,店庆费:5000元/年,年度促销费:10000元/年, | W21: 42916
A22: 16 | B22: 湖北杰之行 | C22: 零售 | D22: 黄石 | E22: 直营 | F22: 地铺店 | G22: 黄石新百集合店 | H22: 黄石新百集合店 | I22: 湖北杰之行 | J22: 大金新百百货股份有限公司黄石分公司 | K22: 湖北省黄石市黄石大道678号大金百货黄石新百商场一楼 | L22: 880 | M22: 2015.09.30-2020.06.30(租金:1056000元/年) 营业管理费:3000元/年;店庆费:5000元;刷卡金额1%外卡手续费,刷卡金额2.5%内卡手续费, 第4年起租金递增8% | U22: 销售年超过1000万元/年加提3%作为物业管理费 | W22: 2016.5.31
